Workbook

Sheet registro
A1: data | B1: Dia da semana | C1: Qualidade sono | D1: Sensação ao acordar | E1: Reg. Sono Relógio | G1: PSR | H1: PSE | I1: Escala de DOR(2a. tabela) | J1: Estresse | K1: Minutos treino | L1: Valor Sono
F2: HRV
A3: 46309 | B3: qua | C3: 7 | D3: 6 | E3: 81 | F3: 1 | G3: 7 | H3: 1 | I3: 2 | J3: 6 | K3: 1 | L3: =MEDIAN(C3:D3) -> 6.5
B4: ter | C4: 1 | D4: 1 | E4: 1 | F4: 1 | G4: 1 | H4: 1 | I4: 1 | J4: 1 | K4: 3 | L4: =MEDIAN(C4:D4) -> 1
B5: ter | C5: 1 | D5: 1 | E5: 1 | F5: 1 | G5: 1 | H5: 1 | I5: 1 | J5: 1 | K5: 2 | L5: =MEDIAN(C5:D5) -> 1
B6: ter | C6: 1 | D6: 1 | E6: 1 | F6: 1 | G6: 1 | H6: 1 | I6: 1 | J6: 1 | K6: 4 | L6: =MEDIAN(C6:D6) -> 1
B7: ter | C7: 1 | D7: 1 | E7: 1 | F7: 1 | G7: 1 | H7: 1 | I7: 1 | J7: 1 | K7: 5 | L7: =MEDIAN(C7:D7) -> 1
B8: ter | C8: 1 | D8: 1 | E8: 1 | F8: 1 | G8: 1 | H8: 1 | I8: 1 | J8: 1 | K8: 6 | L8: =MEDIAN(C8:D8) -> 1
B9: ter | C9: 1 | D9: 1 | E9: 1 | F9: 1 | G9: 1 | H9: 1 | I9: 1 | J9: 1 | K9: 7 | L9: =MEDIAN(C9:D9) -> 1
B10: ter | C10: 1 | D10: 1 | E10: 1 | F10: 1 | G10: 1 | H10: 1 | I10: 1 | J10: 1 | K10: 8 | L10: =MEDIAN(C10:D10) -> 1
B11: ter | C11: 1 | D11: 1 | E11: 1 | F11: 1 | G11: 1 | H11: 1 | I11: 1 | J11: 1 | K11: 9 | L11: =MEDIAN(C11:D11) -> 1
B12: ter | C12: 1 | D12: 1 | E12: 1 | F12: 1 | G12: 1 | H12: 1 | I12: 1 | J12: 1 | K12: 10 | L12: =MEDIAN(C12:D12) -> 1
B13: ter | C13: 1 | D13: 1 | E13: 1 | F13: 1 | G13: 1 | H13: 1 | I13: 1 | J13: 1 | K13: 11 | L13: =MEDIAN(C13:D13) -> 1
B14: ter | C14: 1 | D14: 1 | E14: 1 | F14: 1 | G14: 1 | H14: 1 | I14: 1 | J14: 1 | K14: 12 | L14: =MEDIAN(C14:D14) -> 1
B15: ter | C15: 1 | D15: 1 | E15: 1 | F15: 1 | G15: 1 | H15: 1 | I15: 1 | J15: 1 | K15: 13 | L15: =MEDIAN(C15:D15) -> 1
... B32: ter | C32: 1 | D32: 1 | E32: 1 | F32: 1 | G32: 1 | H32: 1 | I32: 1 | J32: 1 | K32: 30 | L32: =MEDIAN(C32:D32) -> 1

Sheet dados junho
A1: data | B1: treino | C1: dias de treino | D1: avaliação sono | E1: Escala de DOR | F1: Pont relógio | G1: % Recup. sono | H1: Dia semana | I1: PSR | J1: PSE | K1: Min | L1: TRIMP | M1: TSS | N1: TSS Cronico | O1: ATL (TRIMP) | P1: CTL | Q1: TSB | R1: soma diaria | S1: Soma Semanal | T1: Mono diaria | U1: Strain | V1: Nivel Prontidão | W1: monotonia sem | X1: Coef. de variação | Y1: lim inferior | Z1: lim superior | AA1: Fator esc. TSS | AC1: [(10 - PSE) + (10 - Dor) + (10 - Fadiga) + (10 - Estresse) + Média_Sono + Hidratação] / 6 * 2
A2: =registro!A3 -> 46309 | B2: 1 | C2: =COUNTIF(K2:K8,"<>0") -> 7 | D2: =registro!L3 -> 6.5 | E2: =registro!I3 -> 2 | F2: =registro!E3 -> 81 | G2: =F2/10 -> 8.1 | H2: =IFERROR(__xludf.DUMMYFUNCTION("ARRAYFORMULA(IMPORTRANGE(""https://docs.google.com/spreadsheets/d/1EF54ZJ93jh82ntQQ2yoU0GcWtL4Mf3KldBaQIGhLBaU/edit#gid=341599188&range=B3:B30"", ""b3:b30""))"),"seg") -> seg | I2: =registro!G3 -> 7 | J2: =registro!H3 -> 1 | K2: =registro!K3 -> 1 | L2: =J2*K2 -> 1 | M2: =(K2*J2*AA2)/10 -> 0.08 | N2: 0 | O2: =L2 * (0.9 ^ (B2 - 1)) -> 1 | P2: 0 | Q2: =P2-O2 -> -1 | R2: =J2*K2 -> 1 | S2: =sum(R2:R8) -> 28 | T2: 0 | U2: 0 | V2: =(((I2+D2+J2)/30)*100)-(((K2*E2)/1000)*100) -> 48.133333 | W2: =IF(R8=0,0.1,S4/(STDEV(R2:R8))) -> 1.8516402 | X2: =((STDEV(R2:R8))/S4)*100 -> 54.006172 | Y2: 0.8 | Z2: 1.3 | AA2: 0.8 | AB2: =COUNTIF(R2:R10,"<>0") -> 9
A3: =registro!A4 | B3: 2 | D3: =registro!L4 -> 1 | E3: =registro!I4 -> 1 | F3: =registro!E4 -> 1 | G3: =F3/10 -> 0.1 | H3: =IFERROR(__xludf.DUMMYFUNCTION("""COMPUTED_VALUE"""),"ter") -> ter | I3: =registro!G4 -> 1 | J3: =registro!H4 -> 1 | K3: =registro!K4 -> 3 | L3: =J3*K3 -> 3 | M3: =(K3*J3*AA3)/10 -> 0.24 | N3: 0 | O3: =L3 * (0.9 ^ (B3 - 1)) -> 2.7 | P3: =P2+(O3-P2)*(1-EXP(-1/7)) -> 0.35942967 | Q3: =P3-O3 -> -2.3405703 | R3: =J3*K3 -> 3 | S3: C.Med | T3: =((SUM($R$2:$R$3)/COUNTIF($R$2:R3,"<>0"))/STDEV($R$2:$R$3)) -> 1.4142136 | U3: =SUM(R2:R3)*T3 -> 5.6568542 | V3: =(((I3+D3+J3)/30)*100)-(((K3*E3)/1000)*100) -> 9.7 | W3: =IF(R9=0,0.1,S11/(STDEV(R9:R15))) -> 5.0920105 | X3: =IF(R15=0,0.1,((STDEV(R9:R15))/S11)*100) -> 19.638608 | Y3: 0.8 | Z3: 1.3 | AA3: 0.8
A4: =registro!A5 | B4: 3 | D4: =registro!L5 -> 1 | E4: =registro!I5 -> 1 | F4: =registro!E5 -> 1 | G4: =F4/10 -> 0.1 | H4: =IFERROR(__xludf.DUMMYFUNCTION("""COMPUTED_VALUE"""),"qua") -> qua | I4: =registro!G5 -> 1 | J4: =registro!H5 -> 1 | K4: =registro!K5 -> 2 | L4: =J4*K4 -> 2 | M4: =(K4*J4*AA4)/10 -> 0.16 | N4: 0 | O4: =L4 * (0.9 ^ (B4 - 1)) -> 1.62 | P4: =P3+(O4-P3)*(1-EXP(-1/7)) -> 0.52723944 | Q4: =P4-O4 -> -1.0927606 | R4: =J4*K4 -> 2 | S4: =IF(C2=0,"0",(SUM(R2:R8)/C2)) -> 4 | T4: =((SUM($R$2:R4)/COUNTIF($R$2:R4,"<>0"))/STDEV($R$2:R4)) -> 2 | U4: =SUM(R2:R4)*T4 -> 12 | V4: =(((I4+D4+J4)/30)*100)-(((K4*E4)/1000)*100) -> 9.8 | W4: =IF(R16=0,0.1,S17/(STDEV(R16:R22))) -> 8.3323809 | X4: =IF(R16=0,0.1,((STDEV(R16:R22))/S17)*100) -> 12.001372 | Y4: 0.8 | Z4: 1.3 | AA4: 0.8
A5: =registro!A6 | B5: 4 | D5: =registro!L6 -> 1 | E5: =registro!I6 -> 1 | F5: =registro!E6 -> 1 | G5: =F5/10 -> 0.1 | H5: =IFERROR(__xludf.DUMMYFUNCTION("""COMPUTED_VALUE"""),"qui") -> qui | I5: =registro!G6 -> 1 | J5: =registro!H6 -> 1 | K5: =registro!K6 -> 4 | L5: =J5*K5 -> 4 | M5: =(K5*J5*AA5)/10 -> 0.32 | N5: 0 | O5: =L5 * (0.9 ^ (B5 - 1)) -> 2.916 | P5: =P4+(O5-P4)*(1-EXP(-1/7)) -> 0.84523626 | Q5: =P5-O5 -> -2.0707637 | R5: =J5*K5 -> 4 | S5: TT min | T5: =((SUM($R$2:R5)/COUNTIF($R$2:R5,"<>0"))/STDEV($R$2:R5)) -> 1.9364917 | U5: =SUM(R2:R5)*T5 -> 19.364917 | V5: =(((I5+D5+J5)/30)*100)-(((K5*E5)/1000)*100) -> 9.6 | W5: =IF(R23=0,0.1,S24/(STDEV(R23:R29))) -> 11.572751 | X5: =IF(R23=0,0.1,((STDEV(R23:R29))/S24)*100) -> 8.6409876 | Y5: 0.8 | Z5: 1.3 | AA5: 0.8
A6: =registro!A7 | B6: 5 | D6: =registro!L7 -> 1 | E6: =registro!I7 -> 1 | F6: =registro!E7 -> 1 | G6: =F6/10 -> 0.1 | H6: =IFERROR(__xludf.DUMMYFUNCTION("""COMPUTED_VALUE"""),"sex") -> sex | I6: =registro!G7 -> 1 | J6: =registro!H7 -> 1 | K6: =registro!K7 -> 5 | L6: =J6*K6 -> 5 | M6: =(K6*J6*AA6)/10 -> 0.4 | N6: 0 | O6: =L6 * (0.9 ^ (B6 - 1)) -> 3.2805 | P6: =P5+(O6-P5)*(1-EXP(-1/7)) -> 1.1694237 | Q6: =P6-O6 -> -2.1110763 | R6: =J6*K6 -> 5 | S6: =SUM(K2:K8) -> 28 | T6: =((SUM($R$2:R6)/COUNTIF($R$2:R6,"<>0"))/STDEV($R$2:R6)) -> 1.8973666 | U6: =SUM(R2:R6)*T6 -> 28.460499 | V6: =(((I6+D6+J6)/30)*100)-(((K6*E6)/1000)*100) -> 9.5 | Y6: 0.8 | Z6: 1.3 | AA6: 0.8
A7: =registro!A8 | B7: 6 | D7: =registro!L8 -> 1 | E7: =registro!I8 -> 1 | F7: =registro!E8 -> 1 | G7: =F7/10 -> 0.1 | H7: =IFERROR(__xludf.DUMMYFUNCTION("""COMPUTED_VALUE"""),"sab") -> sab | I7: =registro!G8 -> 1 | J7: =registro!H8 -> 1 | K7: =registro!K8 -> 6 | L7: =J7*K7 -> 6 | M7: =(K7*J7*AA7)/10 -> 0.48 | N7: 0 | O7: =L7 * (0.9 ^ (B7 - 1)) -> 3.54294 | P7: =P6+(O7-P6)*(1-EXP(-1/7)) -> 1.4853912 | Q7: =P7-O7 -> -2.0575488 | R7: =J7*K7 -> 6 | S7: =S6/C2 -> 4 | T7: =((SUM($R$2:R7)/COUNTIF($R$2:R7,"<>0"))/STDEV($R$2:R7)) -> 1.8708287 | U7: =SUM(R2:R7)*T7 -> 39.287403 | V7: =(((I7+D7+J7)/30)*100)-(((K7*E7)/1000)*100) -> 9.4 | Y7: 0.8 | Z7: 1.3 | AA7: 0.8
A8: =registro!A9 | B8: 7 | D8: =registro!L9 -> 1 | E8: =registro!I9 -> 1 | F8: =registro!E9 -> 1 | G8: =F8/10 -> 0.1 | H8: =IFERROR(__xludf.DUMMYFUNCTION("""COMPUTED_VALUE"""),"dom") -> dom | I8: =registro!G9 -> 1 | J8: =registro!H9 -> 1 | K8: =registro!K9 -> 7 | L8: =J8*K8 -> 7 | M8: =(K8*J8*AA8)/10 -> 0.56 | N8: =IFERROR(AVERAGE(M2:M8), "N/A") -> 0.32 | O8: =L8 * (0.9 ^ (B8 - 1)) -> 3.720087 | P8: =P7+(O8-P7)*(1-EXP(-1/7)) -> 1.7828786 | Q8: =P8-O8 -> -1.9372084 | R8: =J8*K8 -> 7 | T8: =((SUM($R$2:R8)/COUNTIF($R$2:R8,"<>0"))/STDEV($R$2:R8)) -> 1.8516402 | U8: =SUM(R2:R8)*T8 -> 51.845926 | V8: =(((I8+D8+J8)/30)*100)-(((K8*E8)/1000)*100) -> 9.3 | Y8: 0.8 | Z8: 1.3 | AA8: 0.8 | AB8: Pearson PSE PSR | AG8: =correl(I2:I8,J2:J8) -> #DIV/0! | AI8: Pearson PSE Sono | AN8: =correl(J2:J8,D2:D8) -> #DIV/0! | AP8: Pearson PSR Sono | AU8: =correl(I2:I8,D2:D8) -> 1
A9: =registro!A10 | B9: 8 | C9: =COUNTIF(I9:I15,"<>0") -> 7 | D9: =registro!L10 -> 1 | E9: =registro!I10 -> 1 | F9: =registro!E10 -> 1 | G9: =F9/10 -> 0.1 | H9: =IFERROR(__xludf.DUMMYFUNCTION("""COMPUTED_VALUE"""),"seg") -> seg | I9: =registro!G10 -> 1 | J9: =registro!H10 -> 1 | K9: =registro!K10 -> 8 | L9: =J9*K9 -> 8 | M9: =(K9*J9*AA9)/10 -> 0.64 | N9: =AVERAGE(M3:M9) -> 0.4 | O9: =L9 * (0.9 ^ (B9 - 1)) -> 3.8263752 | P9: =P8+(O9-P8)*(1-EXP(-1/7)) -> 2.0549131 | Q9: =P9-O9 -> -1.7714621 | R9: =J9*K9 -> 8 | S9: =sum(R9:R15) -> 77 | T9: =((SUM($R$2:$R$3)/COUNTIF($R$2:R9,"<>0"))/STDEV($R$2:$R$3)) -> 0.35355339 | U9: =SUM(R3:R9)*T9 -> 12.374369 | V9: =(((I9+D9+J9)/30)*100)-(((K9*E9)/1000)*100) -> 9.2 | Y9: 0.8 | Z9: 1.3 | AA9: 0.8
A10: =registro!A11 | B10: 9 | D10: =registro!L11 -> 1 | E10: =registro!I11 -> 1 | F10: =registro!E11 -> 1 | G10: =F10/10 -> 0.1 | H10: =IFERROR(__xludf.DUMMYFUNCTION("""COMPUTED_VALUE"""),"ter") -> ter | I10: =registro!G11 -> 1 | J10: =registro!H11 -> 1 | K10: =registro!K11 -> 9 | L10: =J10*K10 -> 9 | M10: =(K10*J10*AA10)/10 -> 0.72 | N10: =IFERROR(AVERAGE(M4:M10), "N/A") -> 0.46857143 | O10: =L10 * (0.9 ^ (B10 - 1)) -> 3.8742049 | P10: =P9+(O10-P9)*(1-EXP(-1/7)) -> 2.2971011 | Q10: =P10-O10 -> -1.5771038 | R10: =J10*K10 -> 9 | S10: C.Med | T10: =((SUM($R$2:R10)/COUNTIF($R$2:R10,"<>0"))/STDEV($R$2:R10)) -> 1.8257419 | U10: =SUM(R4:R10)*T10 -> 74.855416 | V10: =(((I10+D10+J10)/30)*100)-(((K10*E10)/1000)*100) -> 9.1 | Y10: 0.8 | Z10: 1.3 | AA10: 0.8
A11: =registro!A12 | B11: 10 | D11: =registro!L12 -> 1 | E11: =registro!I12 -> 1 | F11: =registro!E12 -> 1 | G11: =F11/10 -> 0.1 | H11: =IFERROR(__xludf.DUMMYFUNCTION("""COMPUTED_VALUE"""),"qua") -> qua | I11: =registro!G12 -> 1 | J11: =registro!H12 -> 1 | K11: =registro!K12 -> 10 | L11: =J11*K11 -> 10 | M11: =(K11*J11*AA11)/10 -> 0.8 | N11: =IFERROR(AVERAGE(M5:M11), "N/A") -> 0.56 | O11: =L11 * (0.9 ^ (B11 - 1)) -> 3.8742049 | P11: =P10+(O11-P10)*(1-EXP(-1/7)) -> 2.5070484 | Q11: =P11-O11 -> -1.3671564 | R11: =J11*K11 -> 10 | S11: =IF(C9=0,"0",(SUM(R9:R15)/C9)) -> 11 | T11: =((SUM($R$2:R11)/COUNTIF($R$2:R11,"<>0"))/STDEV($R$2:R11)) -> 1.8165902 | U11: =SUM(R5:R11)*T11 -> 89.01292 | V11: =(((I11+D11+J11)/30)*100)-(((K11*E11)/1000)*100) -> 9 | Y11: 0.8 | Z11: 1.3 | AA11: 0.8
A12: =registro!A13 | B12: 11 | D12: =registro!L13 -> 1 | E12: =registro!I13 -> 1 | F12: =registro!E13 -> 1 | G12: =F12/10 -> 0.1 | H12: =IFERROR(__xludf.DUMMYFUNCTION("""COMPUTED_VALUE"""),"qui") -> qui | I12: =registro!G13 -> 1 | J12: =registro!H13 -> 1 | K12: =registro!K13 -> 11 | L12: =J12*K12 -> 11 | M12: =(K12*J12*AA12)/10 -> 0.88 | N12: =AVERAGE(M6:M12) -> 0.64 | O12: =L12 * (0.9 ^ (B12 - 1)) -> 3.8354628 | P12: =P11+(O12-P11)*(1-EXP(-1/7)) -> 2.6838898 | Q12: =P12-O12 -> -1.1515731 | R12: =J12*K12 -> 11 | S12: TT min | T12: =((SUM($R$2:R12)/COUNTIF($R$2:R12,"<>0"))/STDEV($R$2:R12)) -> 1.8090681 | U12: =SUM(R6:R12)*T12 -> 101.30781 | V12: =(((I12+D12+J12)/30)*100)-(((K12*E12)/1000)*100) -> 8.9 | Y12: 0.8 | Z12: 1.3 | AA12: 0.8
A13: =registro!A14 | B13: 12 | D13: =registro!L14 -> 1 | E13: =registro!I14 -> 1 | F13: =registro!E14 -> 1 | G13: =F13/10 -> 0.1 | H13: =IFERROR(__xludf.DUMMYFUNCTION("""COMPUTED_VALUE"""),"sex") -> sex | I13: =registro!G14 -> 1 | J13: =registro!H14 -> 1 | K13: =registro!K14 -> 12 | L13: =J13*K13 -> 12 | M13: =(K13*J13*AA13)/10 -> 0.96 | N13: =IFERROR(AVERAGE(M7:M13), "N/A") -> 0.72 | O13: =L13 * (0.9 ^ (B13 - 1)) -> 3.7657272 | P13: =P12+(O13-P12)*(1-EXP(-1/7)) -> 2.8279062 | Q13: =P13-O13 -> -0.93782093 | R13: =J13*K13 -> 12 | S13: =SUM(K9:K15) -> 77 | T13: =((SUM($R$2:R13)/COUNTIF($R$2:R13,"<>0"))/STDEV($R$2:R13)) -> 1.8027756 | U13: =SUM(R7:R13)*T13 -> 113.57487 | V13: =(((I13+D13+J13)/30)*100)-(((K13*E13)/1000)*100) -> 8.8 | Y13: 0.8 | Z13: 1.3 | AA13: 0.8
A14: =registro!A15 | B14: 13 | D14: =registro!L15 -> 1 | E14: =registro!I15 -> 1 | F14: =registro!E15 -> 1 | G14: =F14/10 -> 0.1 | H14: =IFERROR(__xludf.DUMMYFUNCTION("""COMPUTED_VALUE"""),"sab") -> sab | I14: =registro!G15 -> 1 | J14: =registro!H15 -> 1 | K14: =registro!K15 -> 13 | L14: =J14*K14 -> 13 | M14: =(K14*J14*AA14)/10 -> 1.04 | N14: =IFERROR(AVERAGE(M8:M14), "N/A") -> 0.8 | O14: =L14 * (0.9 ^ (B14 - 1)) -> 3.671584 | P14: =P13+(O14-P13)*(1-EXP(-1/7)) -> 2.9402184 | Q14: =P14-O14 -> -0.7313656 | R14: =J14*K14 -> 13 | S14: =S13/C9 -> 11 | T14: =((SUM($R$2:R14)/COUNTIF($R$2:R14,"<>0"))/STDEV($R$2:R14)) -> 1.7974341 | U14: =SUM(R8:R14)*T14 -> 125.82038 | V14: =(((I14+D14+J14)/30)*100)-(((K14*E14)/1000)*100) -> 8.7 | Y14: 0.8 | Z14: 1.3 | AA14: 0.8
A15: =registro!A16 | B15: 14 | D15: =registro!L16 -> 1 | E15: =registro!I16 -> 1 | F15: =registro!E16 -> 1 | G15: =F15/10 -> 0.1 | H15: =IFERROR(__xludf.DUMMYFUNCTION("""COMPUTED_VALUE"""),"dom") -> dom | I15: =registro!G16 -> 1 | J15: =registro!H16 -> 1 | K15: =registro!K16 -> 14 | L15: =J15*K15 -> 14 | M15: =(K15*J15*AA15)/10 -> 1.12 | N15: =AVERAGE(M9:M15) -> 0.88 | O15: =L15 * (0.9 ^ (B15 - 1)) -> 3.5586122 | P15: =P14+(O15-P14)*(1-EXP(-1/7)) -> 3.0225403 | Q15: =P15-O15 -> -0.5360719 | R15: =J15*K15 -> 14 | T15: =((SUM($R$2:$R$3)/COUNTIF($R$2:R15,"<>0"))/STDEV($R$2:$R$3)) -> 0.20203051 | U15: =SUM(R9:R15)*T15 -> 15.556349 | V15: =(((I15+D15+J15)/30)*100)-(((K15*E15)/1000)*100) -> 8.6 | Y15: 0.8 | Z15: 1.3 | AA15: 0.8 | AB15: Pearson PSE PSR | AG15: =correl(I9:I15,J9:J15) -> #DIV/0! | AI15: Pearson PSE Sono | AN15: =correl(G9:G15,J9:J15) -> #DIV/0! | AP15: Pearson PSR Sono | AU15: =correl(E9:E15,I9:I15) -> #DIV/0!
A16: =registro!A17 | B16: 15 | C16: =COUNTIF(I16:I22,"<>0") -> 7 | D16: =registro!L17 -> 1 | E16: =registro!I17 -> 1 | F16: =registro!E17 -> 1 | G16: =F16/10 -> 0.1 | H16: =IFERROR(__xludf.DUMMYFUNCTION("""COMPUTED_VALUE"""),"seg") -> seg | I16: =registro!G17 -> 1 | J16: =registro!H17 -> 1 | K16: =registro!K17 -> 15 | L16: =J16*K16 -> 15 | M16: =(K16*J16*AA16)/10 -> 1.2 | N16: =IFERROR(AVERAGE(M10:M16), "N/A") -> 0.96 | O16: =L16 * (0.9 ^ (B16 - 1)) -> 3.4315189 | P16: =P15+(O16-P15)*(1-EXP(-1/7)) -> 3.0769843 | Q16: =P16-O16 -> -0.35453452 | R16: =J16*K16 -> 15 | S16: C.Med | T16: =((SUM($R$2:R16)/COUNTIF($R$2:R16,"<>0"))/STDEV($R$2:R16)) -> 1.7888544 | U16: =SUM(R10:R16)*T16 -> 150.26377 | V16: =(((I16+D16+J16)/30)*100)-(((K16*E16)/1000)*100) -> 8.5 | Y16: 0.8 | Z16: 1.3 | AA16: 0.8
A17: =registro!A18 | B17: 16 | D17: =registro!L18 -> 1 | E17: =registro!I18 -> 1 | F17: =registro!E18 -> 1 | G17: =F17/10 -> 0.1 | H17: =IFERROR(__xludf.DUMMYFUNCTION("""COMPUTED_VALUE"""),"ter") -> ter | I17: =registro!G18 -> 1 | J17: =registro!H18 -> 1 | K17: =registro!K18 -> 16 | L17: =J17*K17 -> 16 | M17: =(K17*J17*AA17)/10 -> 1.28 | N17: =IFERROR(AVERAGE(M11:M17), "N/A") -> 1.04 | O17: =L17 * (0.9 ^ (B17 - 1)) -> 3.2942581 | P17: =P16+(O17-P16)*(1-EXP(-1/7)) -> 3.1059083 | Q17: =P17-O17 -> -0.18834982 | R17: =J17*K17 -> 16 | S17: =IF(C16=0,"0",(SUM(R16:R22)/C16)) -> 18 | T17: =((SUM($R$2:R17)/COUNTIF($R$2:R17,"<>0"))/STDEV($R$2:R17)) -> 1.7853571 | U17: =SUM(R11:R17)*T17 -> 162.4675 | V17: =(((I17+D17+J17)/30)*100)-(((K17*E17)/1000)*100) -> 8.4 | Y17: 0.8 | Z17: 1.3 | AA17: 0.8
A18: =registro!A19 | B18: 17 | D18: =registro!L19 -> 1 | E18: =registro!I19 -> 1 | F18: =registro!E19 -> 1 | G18: =F18/10 -> 0.1 | H18: =IFERROR(__xludf.DUMMYFUNCTION("""COMPUTED_VALUE"""),"qua") -> qua | I18: =registro!G19 -> 1 | J18: =registro!H19 -> 1 | K18: =registro!K19 -> 17 | L18: =J18*K18 -> 17 | M18: =(K18*J18*AA18)/10 -> 1.36 | N18: =AVERAGE(M12:M18) -> 1.12 | O18: =L18 * (0.9 ^ (B18 - 1)) -> 3.1501343 | P18: =P17+(O18-P17)*(1-EXP(-1/7)) -> 3.1117958 | Q18: =P18-O18 -> -0.03833857 | R18: =J18*K18 -> 17 | S18: TT min | T18: =((SUM($R$2:R18)/COUNTIF($R$2:R18,"<>0"))/STDEV($R$2:R18)) -> 1.7822656 | U18: =SUM(R12:R18)*T18 -> 174.66203 | V18: =(((I18+D18+J18)/30)*100)-(((K18*E18)/1000)*100) -> 8.3 | Y18: 0.8 | Z18: 1.3 | AA18: 0.8
A19: =registro!A20 | B19: 18 | D19: =registro!L20 -> 1 | E19: =registro!I20 -> 1 | F19: =registro!E20 -> 1 | G19: =F19/10 -> 0.1 | H19: =IFERROR(__xludf.DUMMYFUNCTION("""COMPUTED_VALUE"""),"qui") -> qui | I19: =registro!G20 -> 1 | J19: =registro!H20 -> 1 | K19: =registro!K20 -> 18 | L19: =J19*K19 -> 18 | M19: =(K19*J19*AA19)/10 -> 1.44 | N19: =IFERROR(AVERAGE(M13:M19), "N/A") -> 1.2 | O19: =L19 * (0.9 ^ (B19 - 1)) -> 3.0018927 | P19: =P18+(O19-P18)*(1-EXP(-1/7)) -> 3.0971652 | Q19: =P19-O19 -> 0.095272521 | R19: =J19*K19 -> 18 | S19: =SUM(K16:K21) -> 105 | T19: =((SUM($R$2:R19)/COUNTIF($R$2:R19,"<>0"))/STDEV($R$2:R19)) -> 1.779513 | U19: =SUM(R13:R19)*T19 -> 186.84887 | V19: =(((I19+D19+J19)/30)*100)-(((K19*E19)/1000)*100) -> 8.2 | Y19: 0.8 | Z19: 1.3 | AA19: 0.8
A20: =registro!A21 | B20: 19 | D20: =registro!L21 -> 1 | E20: =registro!I21 -> 1 | F20: =registro!E21 -> 1 | G20: =F20/10 -> 0.1 | H20: =IFERROR(__xludf.DUMMYFUNCTION("""COMPUTED_VALUE"""),"sex") -> sex | I20: =registro!G21 -> 1 | J20: =registro!H21 -> 1 | K20: =registro!K21 -> 19 | L20: =J20*K20 -> 19 | M20: =(K20*J20*AA20)/10 -> 1.52 | N20: =IFERROR(AVERAGE(M14:M20), "N/A") -> 1.28 | O20: =L20 * (0.9 ^ (B20 - 1)) -> 2.8517981 | P20: =P19+(O20-P19)*(1-EXP(-1/7)) -> 3.0645014 | Q20: =P20-O20 -> 0.21270336 | R20: =J20*K20 -> 19 | S20: =S19/C16 -> 15 | T20: =((SUM($R$2:R20)/COUNTIF($R$2:R20,"<>0"))/STDEV($R$2:R20)) -> 1.7770466 | U20: =SUM(R14:R20)*T20 -> 199.02922 | V20: =(((I20+D20+J20)/30)*100)-(((K20*E20)/1000)*100) -> 8.1 | Y20: 0.8 | Z20: 1.3 | AA20: 0.8
A21: =registro!A22 | B21: 20 | D21: =registro!L22 -> 1 | E21: =registro!I22 -> 1 | F21: =registro!E22 -> 1 | G21: =F21/10 -> 0.1 | H21: =IFERROR(__xludf.DUMMYFUNCTION("""COMPUTED_VALUE"""),"sab") -> sab | I21: =registro!G22 -> 1 | J21: =registro!H22 -> 1 | K21: =registro!K22 -> 20 | L21: =J21*K21 -> 20 | M21: =(K21*J21*AA21)/10 -> 1.6 | N21: =AVERAGE(M15:M21) -> 1.36 | O21: =L21 * (0.9 ^ (B21 - 1)) -> 2.7017034 | P21: =P20+(O21-P20)*(1-EXP(-1/7)) -> 3.016205 | Q21: =P21-O21 -> 0.31450157 | R21: =J21*K21 -> 20 | T21: =((SUM($R$2:$R$3)/COUNTIF($R$2:R21,"<>0"))/STDEV($R$2:$R$3)) -> 0.14142136 | U21: =SUM(R15:R21)*T21 -> 16.829141 | V21: =(((I21+D21+J21)/30)*100)-(((K21*E21)/1000)*100) -> 8 | Y21: 0.8 | Z21: 1.3 | AA21: 0.8
A22: =registro!A23 | B22: 21 | D22: =registro!L23 -> 1 | E22: =registro!I23 -> 1 | F22: =registro!E23 -> 1 | G22: =F22/10 -> 0.1 | H22: =IFERROR(__xludf.DUMMYFUNCTION("""COMPUTED_VALUE"""),"dom") -> dom | I22: =registro!G23 -> 1 | J22: =registro!H23 -> 1 | K22: =registro!K23 -> 21 | L22: =J22*K22 -> 21 | M22: =(K22*J22*AA22)/10 -> 1.68 | N22: =IFERROR(AVERAGE(M16:M22), "N/A") -> 1.44 | O22: =L22 * (0.9 ^ (B22 - 1)) -> 2.5531097 | P22: =P21+(O22-P21)*(1-EXP(-1/7)) -> 2.9545568 | Q22: =P22-O22 -> 0.40144704 | R22: =J22*K22 -> 21 | T22: =((SUM($R$2:R22)/COUNTIF($R$2:R22,"<>0"))/STDEV($R$2:R22)) -> 1.7728105 | U22: =SUM(R16:R22)*T22 -> 223.37413 | V22: =(((I22+D22+J22)/30)*100)-(((K22*E22)/1000)*100) -> 7.9 | Y22: 0.8 | Z22: 1.3 | AA22: 0.8 | AB22: Pearson PSE PSR | AG22: =correl(I16:I22,J16:J22) -> #DIV/0! | AI22: Pearson PSE Sono | AN22: =correl(G16:G22,J16:J22) -> #DIV/0! | AP22: Pearson PSR Sono | AU22: =correl(E16:E22,I16:I22) -> #DIV/0!
A23: =registro!A24 | B23: 22 | C23: =COUNTIF(I23:I29,"<>0") -> 7 | D23: =registro!L24 -> 1 | E23: =registro!I24 -> 1 | F23: =registro!E24 -> 1 | G23: =F23/10 -> 0.1 | H23: =IFERROR(__xludf.DUMMYFUNCTION("""COMPUTED_VALUE"""),"seg") -> seg | I23: =registro!G24 -> 1 | J23: =registro!H24 -> 1 | K23: =registro!K24 -> 22 | L23: =J23*K23 -> 22 | M23: =(K23*J23*AA23)/10 -> 1.76 | N23: =IFERROR(AVERAGE(M17:M23), "N/A") -> 1.52 | O23: =L23 * (0.9 ^ (B23 - 1)) -> 2.4072178 | P23: =P22+(O23-P22)*(1-EXP(-1/7)) -> 2.8816939 | Q23: =P23-O23 -> 0.47447611 | R23: =J23*K23 -> 22 | S23: C.Med | T23: =((SUM($R$2:R23)/COUNTIF($R$2:R23,"<>0"))/STDEV($R$2:R23)) -> 1.7709782 | U23: =SUM(R17:R23)*T23 -> 235.5401 | V23: =(((I23+D23+J23)/30)*100)-(((K23*E23)/1000)*100) -> 7.8 | Y23: 0.8 | Z23: 1.3 | AA23: 0.8
A24: =registro!A25 | B24: 23 | D24: =registro!L25 -> 1 | E24: =registro!I25 -> 1 | F24: =registro!E25 -> 1 | G24: =F24/10 -> 0.1 | H24: =IFERROR(__xludf.DUMMYFUNCTION("""COMPUTED_VALUE"""),"ter") -> ter | I24: =registro!G25 -> 1 | J24: =registro!H25 -> 1 | K24: =registro!K25 -> 23 | L24: =J24*K24 -> 23 | M24: =(K24*J24*AA24)/10 -> 1.84 | N24: =AVERAGE(M18:M24) -> 1.6 | O24: =L24 * (0.9 ^ (B24 - 1)) -> 2.2649731 | P24: =P23+(O24-P23)*(1-EXP(-1/7)) -> 2.7995947 | Q24: =P24-O24 -> 0.53462163 | R24: =J24*K24 -> 23 | S24: =AVERAGE(R23:R29) -> 25 | T24: =((SUM($R$2:R24)/COUNTIF($R$2:R24,"<>0"))/STDEV($R$2:R24)) -> 1.7693035 | U24: =SUM(R18:R24)*T24 -> 247.70249 | V24: =(((I24+D24+J24)/30)*100)-(((K24*E24)/1000)*100) -> 7.7 | Y24: 0.8 | Z24: 1.3 | AA24: 0.8
A25: =registro!A26 | B25: 24 | D25: =registro!L26 -> 1 | E25: =registro!I26 -> 1 | F25: =registro!E26 -> 1 | G25: =F25/10 -> 0.1 | H25: =IFERROR(__xludf.DUMMYFUNCTION("""COMPUTED_VALUE"""),"qua") -> qua | I25: =registro!G26 -> 1 | J25: =registro!H26 -> 1 | K25: =registro!K26 -> 24 | L25: =J25*K25 -> 24 | M25: =(K25*J25*AA25)/10 -> 1.92 | N25: =IFERROR(AVERAGE(M19:M25), "N/A") -> 1.68 | O25: =L25 * (0.9 ^ (B25 - 1)) -> 2.1271051 | P25: =P24+(O25-P24)*(1-EXP(-1/7)) -> 2.7100715 | Q25: =P25-O25 -> 0.58296633 | R25: =J25*K25 -> 24 | S25: TT min | T25: =((SUM($R$2:R25)/COUNTIF($R$2:R25,"<>0"))/STDEV($R$2:R25)) -> 1.767767 | U25: =SUM(R19:R25)*T25 -> 259.86174 | V25: =(((I25+D25+J25)/30)*100)-(((K25*E25)/1000)*100) -> 7.6 | Y25: 0.8 | Z25: 1.3 | AA25: 0.8
A26: =registro!A27 | B26: 25 | D26: =registro!L27 -> 1 | E26: =registro!I27 -> 1 | F26: =registro!E27 -> 1 | G26: =F26/10 -> 0.1 | H26: =IFERROR(__xludf.DUMMYFUNCTION("""COMPUTED_VALUE"""),"qui") -> qui | I26: =registro!G27 -> 1 | J26: =registro!H27 -> 1 | K26: =registro!K27 -> 25 | L26: =J26*K26 -> 25 | M26: =(K26*J26*AA26)/10 -> 2 | N26: =IFERROR(AVERAGE(M20:M26), "N/A") -> 1.76 | O26: =L26 * (0.9 ^ (B26 - 1)) -> 1.9941611 | P26: =P25+(O26-P25)*(1-EXP(-1/7)) -> 2.614768 | Q26: =P26-O26 -> 0.62060691 | R26: =J26*K26 -> 25 | S26: =SUM(K23:K29) -> 175 | T26: =((SUM($R$2:R26)/COUNTIF($R$2:R26,"<>0"))/STDEV($R$2:R26)) -> 1.7663522 | U26: =SUM(R20:R26)*T26 -> 272.01823 | V26: =(((I26+D26+J26)/30)*100)-(((K26*E26)/1000)*100) -> 7.5 | Y26: 0.8 | Z26: 1.3 | AA26: 0.8
A27: =registro!A28 | B27: 26 | D27: =registro!L28 -> 1 | E27: =registro!I28 -> 1 | F27: =registro!E28 -> 1 | G27: =F27/10 -> 0.1 | H27: =IFERROR(__xludf.DUMMYFUNCTION("""COMPUTED_VALUE"""),"sex") -> sex | I27: =registro!G28 -> 1 | J27: =registro!H28 -> 1 | K27: =registro!K28 -> 26 | L27: =J27*K27 -> 26 | M27: =(K27*J27*AA27)/10 -> 2.08 | N27: =AVERAGE(M21:M27) -> 1.84 | O27: =L27 * (0.9 ^ (B27 - 1)) -> 1.8665348 | P27: =P26+(O27-P26)*(1-EXP(-1/7)) -> 2.5151616 | Q27: =P27-O27 -> 0.64862684 | R27: =J27*K27 -> 26 | S27: =S26/C23 -> 25 | T27: =((SUM($R$2:R27)/COUNTIF($R$2:R27,"<>0"))/STDEV($R$2:R27)) -> 1.7650452 | U27: =SUM(R21:R27)*T27 -> 284.17228 | V27: =(((I27+D27+J27)/30)*100)-(((K27*E27)/1000)*100) -> 7.4 | Y27: 0.8 | Z27: 1.3 | AA27: 0.8
A28: =registro!A29 | B28: 27 | D28: =registro!L29 -> 1 | E28: =registro!I29 -> 1 | F28: =registro!E29 -> 1 | G28: =F28/10 -> 0.1 | H28: =IFERROR(__xludf.DUMMYFUNCTION("""COMPUTED_VALUE"""),"sab") -> sab | I28: =registro!G29 -> 1 | J28: =registro!H29 -> 1 | K28: =registro!K29 -> 27 | L28: =J28*K28 -> 27 | M28: =(K28*J28*AA28)/10 -> 2.16 | N28: =IFERROR(AVERAGE(M22:M28), "N/A") -> 1.92 | O28: =L28 * (0.9 ^ (B28 - 1)) -> 1.7444921 | P28: =P27+(O28-P27)*(1-EXP(-1/7)) -> 2.4125685 | Q28: =P28-O28 -> 0.66807635 | R28: =J28*K28 -> 27 | T28: =((SUM($R$2:R28)/COUNTIF($R$2:R28,"<>0"))/STDEV($R$2:R28)) -> 1.7638342 | U28: =SUM(R22:R28)*T28 -> 296.32415 | V28: =(((I28+D28+J28)/30)*100)-(((K28*E28)/1000)*100) -> 7.3 | Y28: 0.8 | Z28: 1.3 | AA28: 0.8
A29: =registro!A30 | B29: 28 | D29: =registro!L30 -> 1 | E29: =registro!I30 -> 1 | F29: =registro!E30 -> 1 | G29: =F29/10 -> 0.1 | H29: =IFERROR(__xludf.DUMMYFUNCTION("""COMPUTED_VALUE"""),"dom") -> dom | I29: =registro!G30 -> 1 | J29: =registro!H30 -> 1 | K29: =registro!K30 -> 28 | L29: =J29*K29 -> 28 | M29: =(K29*J29*AA29)/10 -> 2.24 | N29: =IFERROR(AVERAGE(M23:M29), "N/A") -> 2 | O29: =L29 * (0.9 ^ (B29 - 1)) -> 1.6281926 | P29: =P28+(O29-P28)*(1-EXP(-1/7)) -> 2.3081507 | Q29: =P29-O29 -> 0.67995807 | R29: =J29*K29 -> 28 | T29: =((SUM($R$2:R29)/COUNTIF($R$2:R29,"<>0"))/STDEV($R$2:R29)) -> 1.762709 | U29: =SUM(R23:R29)*T29 -> 308.47407 | V29: =(((I29+D29+J29)/30)*100)-(((K29*E29)/1000)*100) -> 7.2 | Y29: 0.8 | Z29: 1.3 | AA29: 0.8
AB30: Pearson PSE PSR | AG30: =correl(I23:I29,J23:J29) -> #DIV/0! | AI30: Pearson PSE Sono | AN30: =correl(G23:G29,J23:J29) -> #DIV/0! | AP30: Pearson PSR Sono | AU30: =correl(E23:E29,I23:I29) -> #DIV/0!
AB31: AVALIAÇÃO CICLO
AB41: Pearson PSE PSR | AG41: =correl(I2:I29,J2:J29) -> #DIV/0! | AI41: Pearson PSE Sono | AN41: =correl(D2:D29,J2:J29) -> #DIV/0! | AO41: Pearson PSR Sono | AT41: =correl(D2:D29,I2:I29) -> 1
AB49: Pearson TSS e TSS Cronico | AI49: =correl(M2:M29,N2:N29) -> 0.99505698

Sheet Registro dor
A1: =IFERROR(__xludf.DUMMYFUNCTION("IMPORTRANGE(""https://docs.google.com/spreadsheets/d/1EF54ZJ93jh82ntQQ2yoU0GcWtL4Mf3KldBaQIGhLBaU"",""Dor!A1:d32"")"),"data") -> data | B1: =IFERROR(__xludf.DUMMYFUNCTION("""COMPUTED_VALUE"""),"escala dor manhã") -> escala dor manhã | C1: =IFERROR(__xludf.DUMMYFUNCTION("""COMPUTED_VALUE"""),"escala de dor meio dia") -> escala de dor meio dia | D1: =IFERROR(__xludf.DUMMYFUNCTION("""COMPUTED_VALUE"""),"escala dor noitinha") -> escala dor noitinha
A2: =IFERROR(__xludf.DUMMYFUNCTION("""COMPUTED_VALUE"""),45432.0) -> 45432
A3: =IFERROR(__xludf.DUMMYFUNCTION("""COMPUTED_VALUE"""),45433.0) -> 45433
A4: =IFERROR(__xludf.DUMMYFUNCTION("""COMPUTED_VALUE"""),45434.0) -> 45434
A5: =IFERROR(__xludf.DUMMYFUNCTION("""COMPUTED_VALUE"""),45435.0) -> 45435
A6: =IFERROR(__xludf.DUMMYFUNCTION("""COMPUTED_VALUE"""),45436.0) -> 45436
A7: =IFERROR(__xludf.DUMMYFUNCTION("""COMPUTED_VALUE"""),45437.0) -> 45437
A8: =IFERROR(__xludf.DUMMYFUNCTION("""COMPUTED_VALUE"""),45438.0) -> 45438
A9: =IFERROR(__xludf.DUMMYFUNCTION("""COMPUTED_VALUE"""),45439.0) -> 45439
A10: =IFERROR(__xludf.DUMMYFUNCTION("""COMPUTED_VALUE"""),45440.0) -> 45440
A11: =IFERROR(__xludf.DUMMYFUNCTION("""COMPUTED_VALUE"""),45441.0) -> 45441
A12: =IFERROR(__xludf.DUMMYFUNCTION("""COMPUTED_VALUE"""),45442.0) -> 45442
A13: =IFERROR(__xludf.DUMMYFUNCTION("""COMPUTED_VALUE"""),45443.0) -> 45443
A14: =IFERROR(__xludf.DUMMYFUNCTION("""COMPUTED_VALUE"""),45444.0) -> 45444
A15: =IFERROR(__xludf.DUMMYFUNCTION("""COMPUTED_VALUE"""),45445.0) -> 45445
A16: =IFERROR(__xludf.DUMMYFUNCTION("""COMPUTED_VALUE"""),45446.0) -> 45446
A17: =IFERROR(__xludf.DUMMYFUNCTION("""COMPUTED_VALUE"""),45447.0) -> 45447
A18: =IFERROR(__xludf.DUMMYFUNCTION("""COMPUTED_VALUE"""),45448.0) -> 45448
A19: =IFERROR(__xludf.DUMMYFUNCTION("""COMPUTED_VALUE"""),45449.0) -> 45449
A20: =IFERROR(__xludf.DUMMYFUNCTION("""COMPUTED_VALUE"""),45450.0) -> 45450
A21: =IFERROR(__xludf.DUMMYFUNCTION("""COMPUTED_VALUE"""),45451.0) -> 45451
A22: =IFERROR(__xludf.DUMMYFUNCTION("""COMPUTED_VALUE"""),45452.0) -> 45452
A23: =IFERROR(__xludf.DUMMYFUNCTION("""COMPUTED_VALUE"""),45453.0) -> 45453
A24: =IFERROR(__xludf.DUMMYFUNCTION("""COMPUTED_VALUE"""),45454.0) -> 45454
A25: =IFERROR(__xludf.DUMMYFUNCTION("""COMPUTED_VALUE"""),45455.0) -> 45455
A26: =IFERROR(__xludf.DUMMYFUNCTION("""COMPUTED_VALUE"""),45456.0) -> 45456
A27: =IFERROR(__xludf.DUMMYFUNCTION("""COMPUTED_VALUE"""),45457.0) -> 45457
A28: =IFERROR(__xludf.DUMMYFUNCTION("""COMPUTED_VALUE"""),45458.0) -> 45458
A29: =IFERROR(__xludf.DUMMYFUNCTION("""COMPUTED_VALUE"""),45459.0) -> 45459
A30: =IFERROR(__xludf.DUMMYFUNCTION("""COMPUTED_VALUE"""),45460.0) -> 45460
A31: =IFERROR(__xludf.DUMMYFUNCTION("""COMPUTED_VALUE"""),45461.0) -> 45461
A32: =IFERROR(__xludf.DUMMYFUNCTION("""COMPUTED_VALUE"""),45462.0) -> 45462

Sheet Página5
A1: DIA | B1: PSE | C1: MINUTOS DE TREINO | D1: FATOR DE ESCALA | E1: TSS (N) | F1: TSS CRÔNICO (O) - MÉDIA MÓVEL DE 7 DIAS
A2: 1 | B2: 5 | C2: 60 | D2: 0.8 | E2: =B2*C2*D2/100 -> 2.4 | F2: =IFERROR(AVERAGE(E2:E8), "N/A") -> 2.3257143
A3: 2 | B3: 6 | C3: 45 | D3: 0.8 | E3: =B3*C3*D3/100 -> 2.16 | F3: =IFERROR(AVERAGE(E3:E9), "N/A") -> 2.4228571
A4: 3 | B4: 7 | C4: 30 | D4: 0.8 | E4: =B4*C4*D4/100 -> 1.68 | F4: =IFERROR(AVERAGE(E4:E10), "N/A") -> 2.4857143
A5: 4 | B5: 4 | C5: 60 | D5: 0.8 | E5: =B5*C5*D5/100 -> 1.92 | F5: =IFERROR(AVERAGE(E5:E11), "N/A") -> 2.5542857
A6: 5 | B6: 5 | C6: 75 | D6: 0.8 | E6: =B6*C6*D6/100 -> 3 | F6: =IFERROR(AVERAGE(E6:E12), "N/A") -> 2.56
A7: 6 | B7: 8 | C7: 50 | D7: 0.8 | E7: =B7*C7*D7/100 -> 3.2 | F7: =IFERROR(AVERAGE(E7:E13), "N/A") -> 2.3828571
A8: 7 | B8: 6 | C8: 40 | D8: 0.8 | E8: =B8*C8*D8/100 -> 1.92 | F8: =AVERAGE(E2:E8) -> 2.3257143
A9: 8 | B9: 7 | C9: 55 | D9: 0.8 | E9: =B9*C9*D9/100 -> 3.08 | F9: =AVERAGE(E3:E9) -> 2.4228571
A10: 9 | B10: 5 | C10: 65 | D10: 0.8 | E10: =B10*C10*D10/100 -> 2.6 | F10: =AVERAGE(E4:E10) -> 2.4857143
A11: 10 | B11: 6 | C11: 45 | D11: 0.8 | E11: =B11*C11*D11/100 -> 2.16 | F11: =AVERAGE(E5:E11) -> 2.5542857
A12: 11 | B12: 7 | C12: 35 | D12: 0.8 | E12: =B12*C12*D12/100 -> 1.96 | F12: =AVERAGE(E6:E12) -> 2.56
A13: 12 | B13: 4 | C13: 55 | D13: 0.8 | E13: =B13*C13*D13/100 -> 1.76 | F13: =AVERAGE(E7:E13) -> 2.3828571
A14: 13 | B14: 5 | C14: 60 | D14: 0.8 | E14: =B14*C14*D14/100 -> 2.4 | F14: =AVERAGE(E8:E14) -> 2.2685714
A15: 14 | B15: 8 | C15: 45 | D15: 0.8 | E15: =B15*C15*D15/100 -> 2.88 | F15: =AVERAGE(E9:E15) -> 2.4057143
A16: 15 | B16: 6 | C16: 50 | D16: 0.8 | E16: =B16*C16*D16/100 -> 2.4 | F16: =AVERAGE(E10:E16) -> 2.3085714
A17: 16 | B17: 7 | C17: 40 | D17: 0.8 | E17: =B17*C17*D17/100 -> 2.24 | F17: =AVERAGE(E11:E17) -> 2.2571429
A18: 17 | B18: 5 | C18: 60 | D18: 0.8 | E18: =B18*C18*D18/100 -> 2.4 | F18: =AVERAGE(E12:E18) -> 2.2914286
A19: 18 | B19: 6 | C19: 45 | D19: 0.8 | E19: =B19*C19*D19/100 -> 2.16 | F19: =AVERAGE(E13:E19) -> 2.32
... A29: 28 | B29: 4 | C29: 55 | D29: 0.8 | E29: =B29*C29*D29/100 -> 1.76 | F29: =AVERAGE(E23:E29) -> 2.3828571

Sheet Variáveis
A1: VARIÁVEL | B1: AVALIA | C1: AUTOR(ES) ORIGINAL(IS) | D1: QUEM FOI O AUTOR
A2: PSR | B2: Perceived Stress Recovery | C2: Kellmann & Kallus, 2001 | D2: Kellmann & Kallus: Kellmann é um psicólogo do esporte conhecido por seu trabalho em recuperação e estresse no esporte. Kallus também contribuiu significativamente para a psicologia do esporte, com foco em avaliação e recuperação.
A3: PSE | B3: Perceived Stress and Energy | C3: Kellmann & Kallus, 2001 | D3: Kellmann & Kallus: (Veja acima)
A4: TRIMP | B4: Training Impulse | C4: Eric Banister, 1991 | D4: Eric Banister: Um pesquisador que desenvolveu o modelo TRIMP para quantificar o volume de treinamento baseado na frequência cardíaca.
A5: TSS | B5: Training Stress Score | C5: Andrew Coggan | D5: Andrew Coggan: Cientista do exercício e autor, conhecido por seu trabalho em treinamento de ciclismo e desenvolvimento de métricas de desempenho.
A6: TSS Crônico | B6: Chronic Training Stress Score (Carga de treinamento crônica) | C6: Andrew Coggan | D6: Andrew Coggan: (Veja acima)
A7: ATL | B7: Acute Training Load (Carga de treinamento aguda)
A8: CTL | B8: Chronic Training Load (Carga de treinamento crônica)
A9: TSB | B9: Training Stress Balance (Balanço de estresse de treinamento)
A10: Monotonia de Treino | B10: Monotony of Training | C10: Foster, 1998 | D10: Carl Foster: Um cientista do esporte e professor, conhecido por seu trabalho em fisiologia do exercício e treinamento esportivo.

Sheet PSE
A1: ESCALA BORG CR10 | B1: PERCEPÇÃO DE ESFORÇO | C1: % ESTIMADO DO VO2 MÁXIMO | D1: INTENSIDADE DO EXERCÍCIO
A2: 0 | B2: Nenhum esforço | C2: 0.1 | D2: Repouso
A3: 1 | B3: Muito leve | C3: 20-30% | D3: Muito leve
A4: 45353 | B4: Leve | C4: 30-40% | D4: Leve
A5: 45416 | B5: Moderado | C5: 40-60% | D5: Moderado
A6: 45479 | B6: Difícil | C6: 60-70% | D6: Intenso
A7: 45543 | B7: Muito difícil | C7: 70-85% | D7: Muito intenso
A8: 10 | B8: Esforço máximo | C8: 85-100% | D8: Máximo

Sheet PSR
A1: CATEGORIA | B1: ESCALA LIKERT | C1: INTERPRETAÇÃO
A2: Muito Baixo Estresse/Alta Recuperação | B2: 45323 | C2: Indica uma percepção muito baixa de estresse e uma excelente recuperação. Ideal para alto desempenho e bem-estar.
A3: Baixo Estresse/Boa Recuperação | B3: 45385 | C3: Indica baixo estresse e boa recuperação. Situação desejável para a maioria das atividades diárias e recuperação adequada.
A4: Moderado Estresse/Moderada Recuperação | B4: 45448 | C4: Níveis moderados de estresse e recuperação. Pode ser sustentável a curto prazo, mas pode exigir ajustes para evitar desgaste.
A5: Alto Estresse/Baixa Recuperação | B5: 45511 | C5: Indica alto estresse e recuperação insuficiente. Sinal de alerta para a necessidade de intervenção para melhorar a recuperação.
A6: Muito Alto Estresse/Muito Baixa Recuperação | B6: 45574 | C6: Níveis críticos de estresse com recuperação muito baixa. Intervenção imediata necessária para prevenir problemas de saúde e desempenho.

Sheet TSS
A1: TSS POR SESSÃO | B1: INTERPRETAÇÃO
A2: 0 - 150 | B2: Baixo: Recuperação ativa ou treino leve. Pode ser realizado diariamente sem causar fadiga excessiva.
A3: 150 - 300 | B3: Moderado: Treino de endurance ou sessões mais intensas. Exige recuperação adequada.
A4: 300 - 450 | B4: Alto: Sessões muito desafiadoras que exigem dias de recuperação e são usadas com moderação no treinamento.
A5: > 450 | B5: Muito Alto: Sessões extremamente duras que exigem recuperação prolongada e são raramente realizadas, a menos que em competições ou situações específicas de treinamento.

Sheet ciclo 2
A1: data | B1: treino | C1: Dia semana | D1: dias de treino | E1: valores sono | F1: PSR | G1: PSE | H1: Min | I1: TRIMP | J1: TSS | K1: TSS Cronico | L1: ATL | M1: CTL | N1: TSB | O1: soma diaria | P1: Soma Semanal | Q1: Mono | R1: lim inferior | S1: lim superior
A2: 45425 | B2: 1 | C2: seg | D2: =COUNTIF(F2:F8,"<>0") -> 2 | E2: 87 | F2: 9 | G2: 6 | H2: 58 | I2: =G2*H2 -> 348 | J2: =(G2*0.64*H2) -> 222.72 | L2: 0 | M2: 0 | N2: 0 | O2: =G2*H2 -> 348 | P2: =sum(O2:O8) -> 774 | Q2: 0 | R2: 0.8 | S2: 1.3
A3: 45426 | B3: 2 | C3: ter | E3: 64 | F3: 6 | G3: 6 | H3: 71 | I3: =G3*H3 -> 426 | J3: =(G3*0.64*H3) -> 272.64 | K3: =sum(J2:J3)/count(J2:J3) -> 247.68 | L3: 0 | M3: 0 | N3: 0 | O3: =G3*H3 -> 426 | P3: C.Med | Q3: 0 | R3: 0.8 | S3: 1.3
B4: 3 | C4: qua | F4: 0 | G4: 0 | H4: 0 | I4: =G4*H4 -> 0 | J4: =(G4*0.64*H4) -> 0 | K4: =SUM(J2:J4)/COUNT(J2:J4) -> 165.12 | L4: 0 | M4: 0 | N4: 0 | O4: =G4*H4 -> 0 | P4: =AVERAGE(O2:O8) -> 110.57143 | Q4: 0 | R4: 0.8 | S4: 1.3
B5: 4 | C5: qui | F5: 0 | G5: 0 | H5: 0 | I5: =G5*H5 -> 0 | J5: =(G5*0.64*H5) -> 0 | K5: =SUM(J2:J5)/COUNT(J2:J5) -> 123.84 | L5: 0 | M5: 0 | N5: 0 | O5: =G5*H5 -> 0 | Q5: 0 | R5: 0.8 | S5: 1.3
B6: 5 | C6: sex | F6: 0 | G6: 0 | H6: 0 | I6: =G6*H6 -> 0 | J6: =(G6*0.64*H6) -> 0 | K6: =SUM(J2:J6)/COUNT(J2:J6) -> 99.072 | L6: 0 | M6: 0 | N6: 0 | O6: =G6*H6 -> 0 | Q6: 0 | R6: 0.8 | S6: 1.3
B7: 6 | C7: sab | F7: 0 | G7: 0 | H7: 0 | I7: =G7*H7 -> 0 | J7: =(G7*0.64*H7) -> 0 | K7: =SUM(J2:J7)/COUNT(J2:J7) -> 82.56 | L7: 0 | M7: 0 | N7: 0 | O7: =G7*H7 -> 0 | Q7: 0 | R7: 0.8 | S7: 1.3
B8: 7 | C8: dom | F8: 0 | G8: 0 | H8: 0 | I8: 0 | J8: =(G8*0.64*H8) -> 0 | K8: =SUM(J2:J8)/COUNT(J2:J8) -> 70.765714 | L8: =SUm(J2:J8)/7 -> 70.765714 | M8: =SUm(L8:L29)/28 -> 3.9183673 | N8: =L8-M8 -> 66.847347 | O8: =G8*H8 -> 0 | Q8: =P4/(STDEV(O2:O8)) -> 0.58142134 | R8: 0.8 | S8: 1.3
B9: 8 | C9: seg | D9: =COUNTIF(F9:F15,"<>0") -> 0 | F9: 0 | G9: 0 | H9: 0 | I9: 0 | J9: =(G9*0.64*H9) -> 0 | K9: =SUM(J2:J9)/COUNT(J2:J9) -> 61.92 | L9: =SUm(J3:J9)/7 -> 38.948571 | M9: =SUm(L9:L30)/28 -> 1.3910204 | N9: =L9-M9 -> 37.557551 | O9: =G9*H9 -> 0 | P9: =sum(O9:O15) -> 0 | Q9: 0 | R9: 0.8 | S9: 1.3
B10: 9 | C10: ter | F10: 0 | G10: 0 | H10: 0 | I10: 0 | J10: =(G10*0.64*H10) -> 0 | K10: =SUM(J2:J10)/COUNT(J2:J10) -> 55.04 | L10: =SUm(J4:J10)/7 -> 0 | M10: =SUm(L10:L31)/28 -> 0 | N10: =L10-M10 -> 0 | O10: =G10*H10 -> 0 | P10: C.Med | Q10: 0 | R10: 0.8 | S10: 1.3
B11: 10 | C11: qua | F11: 0 | G11: 0 | H11: 0 | I11: 0 | J11: =(G11*0.64*H11) -> 0 | K11: =SUM($J$2:J11)/COUNT($J$2:J11) -> 49.536 | L11: =SUm(J5:J11)/7 -> 0 | M11: =SUm(L11:L32)/28 -> 0 | N11: =L11-M11 -> 0 | O11: =G11*H11 -> 0 | P11: =AVERAGE(O9:O15) -> 0 | Q11: 0 | R11: 0.8 | S11: 1.3
B12: 11 | C12: qui | F12: 0 | G12: 0 | H12: 0 | I12: 0 | J12: =(G12*0.64*H12) -> 0 | K12: =SUM($J$2:J12)/COUNT($J$2:J12) -> 45.032727 | L12: =SUm(J6:J12)/7 -> 0 | M12: =SUm(L12:L33)/28 -> 0 | N12: =L12-M12 -> 0 | O12: =G12*H12 -> 0 | Q12: 0 | R12: 0.8 | S12: 1.3
B13: 12 | C13: sex | F13: 0 | G13: 0 | H13: 0 | I13: 0 | J13: =(G13*0.64*H13) -> 0 | K13: =SUM($J$2:J13)/COUNT($J$2:J13) -> 41.28 | L13: =SUm(J7:J13)/7 -> 0 | M13: =SUm(L13:L34)/28 -> 0 | N13: =L13-M13 -> 0 | O13: =G13*H13 -> 0 | Q13: 0 | R13: 0.8 | S13: 1.3
B14: 13 | C14: sab | F14: 0 | G14: 0 | H14: 0 | I14: 0 | J14: =(G14*0.64*H14) -> 0 | K14: =SUM($J$2:J14)/COUNT($J$2:J14) -> 38.104615 | L14: =SUm(J8:J14)/7 -> 0 | M14: =SUm(L14:L35)/28 -> 0 | N14: =L14-M14 -> 0 | O14: =G14*H14 -> 0 | Q14: 0 | R14: 0.8 | S14: 1.3
B15: 14 | C15: Dom | F15: 0 | G15: 0 | H15: 0 | I15: 0 | J15: =(G15*0.64*H15) -> 0 | K15: =SUM($J$2:J15)/COUNT($J$2:J15) -> 35.382857 | L15: =SUm(J9:J15)/7 -> 0 | M15: =SUm(L15:L36)/28 -> 0 | N15: =L15-M15 -> 0 | O15: =G15*H15 -> 0 | Q15: =P11/(STDEV(O9:O15)) -> #DIV/0! | R15: 0.8 | S15: 1.3
B16: 15 | C16: seg | D16: =COUNTIF(F16:F22,"<>0") -> 0 | F16: 0 | G16: 0 | H16: 0 | I16: 0 | J16: =(G16*0.64*H16) -> 0 | K16: =SUM($J$2:J16)/COUNT($J$2:J16) -> 33.024 | L16: =SUm(J10:J16)/7 -> 0 | M16: =SUm(L16:L37)/28 -> 0 | N16: =L16-M16 -> 0 | O16: =G16*H16 -> 0 | P16: =sum(O16:O22) -> 0 | Q16: 0 | R16: 0.8 | S16: 1.3
B17: 16 | C17: ter | F17: 0 | G17: 0 | H17: 0 | I17: 0 | J17: =(G17*0.64*H17) -> 0 | K17: =SUM($J$2:J17)/COUNT($J$2:J17) -> 30.96 | L17: =SUm(J11:J17)/7 -> 0 | M17: =SUm(L17:L38)/28 -> 0 | N17: =L17-M17 -> 0 | O17: =G17*H17 -> 0 | P17: C.Med | Q17: 0 | R17: 0.8 | S17: 1.3
B18: 17 | C18: qua | F18: 0 | G18: 0 | H18: 0 | I18: 0 | J18: =(G18*0.64*H18) -> 0 | K18: =SUM($J$2:J18)/COUNT($J$2:J18) -> 29.138824 | L18: =SUm(J12:J18)/7 -> 0 | M18: =SUm(L18:L39)/28 -> 0 | N18: =L18-M18 -> 0 | O18: =G18*H18 -> 0 | P18: =AVERAGE(O16:O22) -> 0 | Q18: 0 | R18: 0.8 | S18: 1.3
B19: 18 | C19: qui | F19: 0 | G19: 0 | H19: 0 | I19: 0 | J19: =(G19*0.64*H19) -> 0 | K19: =SUM($J$2:J19)/COUNT($J$2:J19) -> 27.52 | L19: =SUm(J13:J19)/7 -> 0 | M19: =SUm(L19:L40)/28 -> 0 | N19: =L19-M19 -> 0 | O19: =G19*H19 -> 0 | Q19: 0 | R19: 0.8 | S19: 1.3
B20: 19 | C20: sex | F20: 0 | G20: 0 | H20: 0 | I20: 0 | J20: =(G20*0.64*H20) -> 0 | K20: =SUM($J$2:J20)/COUNT($J$2:J20) -> 26.071579 | L20: =SUm(J14:J20)/7 -> 0 | M20: =SUm(L20:L41)/28 -> 0 | N20: =L20-M20 -> 0 | O20: =G20*H20 -> 0 | Q20: 0 | R20: 0.8 | S20: 1.3
B21: 20 | C21: sab | F21: 0 | G21: 0 | H21: 0 | I21: 0 | J21: =(G21*0.64*H21) -> 0 | K21: =SUM($J$2:J21)/COUNT($J$2:J21) -> 24.768 | L21: =SUm(J15:J21)/7 -> 0 | M21: =SUm(L21:L42)/28 -> 0 | N21: =L21-M21 -> 0 | O21: =G21*H21 -> 0 | Q21: 0 | R21: 0.8 | S21: 1.3
B22: 21 | C22: Dom | F22: 0 | G22: 0 | H22: 0 | I22: 0 | J22: =(G22*0.64*H22) -> 0 | K22: =SUM($J$2:J22)/COUNT($J$2:J22) -> 23.588571 | L22: =SUm(J16:J22)/7 -> 0 | M22: =SUm(L22:L43)/28 -> 0 | N22: =L22-M22 -> 0 | O22: =G22*H22 -> 0 | Q22: =P18/(STDEV(O16:O22)) -> #DIV/0! | R22: 0.8 | S22: 1.3
B23: 22 | C23: seg | D23: =COUNTIF(F23:F29,"<>0") -> 0 | F23: 0 | G23: 0 | H23: 0 | I23: 0 | J23: =(G23*0.64*H23) -> 0 | K23: =SUM($J$2:J23)/COUNT($J$2:J23) -> 22.516364 | L23: =SUm(J17:J23)/7 -> 0 | M23: =SUm(L23:L44)/28 -> 0 | N23: =L23-M23 -> 0 | O23: =G23*H23 -> 0 | P23: =sum(O23:O29) -> 0 | Q23: 0 | R23: 0.8 | S23: 1.3
B24: 23 | C24: ter | F24: 0 | G24: 0 | H24: 0 | I24: 0 | J24: =(G24*0.64*H24) -> 0 | K24: =SUM($J$2:J24)/COUNT($J$2:J24) -> 21.537391 | L24: =SUm(J18:J24)/7 -> 0 | M24: =SUm(L24:L45)/28 -> 0 | N24: =L24-M24 -> 0 | O24: =G24*H24 -> 0 | P24: C.Med | Q24: 0 | R24: 0.8 | S24: 1.3
B25: 24 | C25: qua | F25: 0 | G25: 0 | H25: 0 | I25: 0 | J25: =(G25*0.64*H25) -> 0 | K25: =SUM($J$2:J25)/COUNT($J$2:J25) -> 20.64 | L25: =SUm(J19:J25)/7 -> 0 | M25: =SUm(L25:L46)/28 -> 0 | N25: =L25-M25 -> 0 | O25: =G25*H25 -> 0 | P25: =AVERAGE(O23:O29) -> 0 | Q25: 0 | R25: 0.8 | S25: 1.3
B26: 25 | C26: qui | F26: 0 | G26: 0 | H26: 0 | I26: 0 | J26: =(G26*0.64*H26) -> 0 | K26: =SUM($J$2:J26)/COUNT($J$2:J26) -> 19.8144 | L26: =SUm(J20:J26)/7 -> 0 | M26: =SUm(L26:L47)/28 -> 0 | N26: =L26-M26 -> 0 | O26: =G26*H26 -> 0 | Q26: 0 | R26: 0.8 | S26: 1.3
B27: 26 | C27: sex | F27: 0 | G27: 0 | H27: 0 | I27: 0 | J27: =(G27*0.64*H27) -> 0 | K27: =SUM($J$2:J27)/COUNT($J$2:J27) -> 19.052308 | L27: =SUm(J21:J27)/7 -> 0 | M27: =SUm(L27:L48)/28 -> 0 | N27: =L27-M27 -> 0 | O27: =G27*H27 -> 0 | Q27: 0 | R27: 0.8 | S27: 1.3
B28: 27 | C28: sab | F28: 0 | G28: 0 | H28: 0 | I28: 0 | J28: =(G28*0.64*H28) -> 0 | K28: =SUM($J$2:J28)/COUNT($J$2:J28) -> 18.346667 | L28: =SUm(J22:J28)/7 -> 0 | M28: =SUm(L28:L49)/28 -> 0 | N28: =L28-M28 -> 0 | O28: =G28*H28 -> 0 | Q28: 0 | R28: 0.8 | S28: 1.3
B29: 28 | C29: Dom | F29: 0 | G29: 0 | H29: 0 | I29: 0 | J29: =(G29*0.64*H29) -> 0 | K29: =SUM($J$2:J29)/COUNT($J$2:J29) -> 17.691429 | L29: =SUm(J23:J29)/7 -> 0 | M29: =SUm(L29:L50)/28 -> 0 | N29: =L29-M29 -> 0 | O29: =G29*H29 -> 0 | Q29: =P25/(STDEV(O23:O29)) -> #DIV/0! | R29: 0.8 | S29: 1.3
Q30: 0
Q31: 0
Q32: 0
Q33: 0
Q34: 0
Q35: 0
Q36: 0
Q37: 0
Q38: 0
Q39: 0
Q40: 0
...

Sheet base
A1: data | B1: treino | C1: Dia semana | D1: dias de treino | E1: PSR | F1: PSE | G1: Min | H1: TRIMP | I1: TSS | J1: TSS Cronico | K1: ATL | L1: CTL | M1: TSB | N1: soma diaria | O1: Soma Semanal | P1: Mono | Q1: lim inferior | R1: lim superior
B2: 1 | C2: seg | D2: =COUNTIF(E2:E8,"<>0") -> 7 | E2: 8 | F2: 6 | G2: 80 | H2: =F2*G2 -> 480 | I2: =(F2*0.64*G2) -> 307.2 | K2: 0 | L2: 0 | M2: 0 | N2: =F2*G2 -> 480 | O2: =sum(N2:N8) -> 2865 | P2: 0 | Q2: 0.8 | R2: 1.3
B3: 2 | C3: ter | E3: 7 | F3: 7 | G3: 95 | H3: =F3*G3 -> 665 | I3: =(F3*0.64*G3) -> 425.6 | J3: =sum(I2:I3)/count(I2:I3) -> 366.4 | K3: 0 | L3: 0 | M3: 0 | N3: =F3*G3 -> 665 | O3: C.Med | P3: 0 | Q3: 0.8 | R3: 1.3
B4: 3 | C4: qua | E4: 7 | F4: 7 | G4: 80 | H4: =F4*G4 -> 560 | I4: =(F4*0.64*G4) -> 358.4 | J4: =SUM(I2:I4)/COUNT(I2:I4) -> 363.73333 | K4: 0 | L4: 0 | M4: 0 | N4: =F4*G4 -> 560 | O4: =AVERAGE(N2:N8) -> 409.28571 | P4: 0 | Q4: 0.8 | R4: 1.3
B5: 4 | C5: qui | E5: 7 | F5: 8 | G5: 85 | H5: =F5*G5 -> 680 | I5: =(F5*0.64*G5) -> 435.2 | J5: =SUM(I2:I5)/COUNT(I2:I5) -> 381.6 | K5: 0 | L5: 0 | M5: 0 | N5: =F5*G5 -> 680 | P5: 0 | Q5: 0.8 | R5: 1.3
B6: 5 | C6: sex | E6: 7 | F6: 6 | G6: 80 | H6: =F6*G6 -> 480 | I6: =(F6*0.64*G6) -> 307.2 | J6: =SUM(I2:I6)/COUNT(I2:I6) -> 366.72 | K6: 0 | L6: 0 | M6: 0 | N6: =F6*G6 -> 480 | P6: 0 | Q6: 0.8 | R6: 1.3
B7: 6 | C7: sab | E7: 8 | F7: 0 | G7: 0 | H7: =F7*G7 -> 0 | I7: =(F7*0.64*G7) -> 0 | J7: =SUM(I2:I7)/COUNT(I2:I7) -> 305.6 | K7: 0 | L7: 0 | M7: 0 | N7: =F7*G7 -> 0 | P7: 0 | Q7: 0.8 | R7: 1.3
B8: 7 | C8: dom | E8: 9 | F8: 0 | G8: 0 | H8: 0 | I8: =(F8*0.64*G8) -> 0 | J8: =SUM(I2:I8)/COUNT(I2:I8) -> 261.94286 | K8: =SUm(I2:I8)/7 -> 261.94286 | L8: =SUm(K8:K30)/28 -> 232.53224 | M8: =K8-L8 -> 29.410612 | N8: =F8*G8 -> 0 | P8: =O4/(STDEV(N2:N8)) -> 1.4087897 | Q8: 0.8 | R8: 1.3
B9: treino | C9: Dia semana | D9: dias de treino | E9: PSR | F9: PSE | G9: Min | H9: TRIMP | I9: TSS | J9: TSS Cronico | K9: ATL | L9: CTL | M9: TSB | N9: =F9*G9 -> #VALUE! | O9: Soma Semanal | P9: Mono | Q9: lim inferior | R9: lim superior
B10: 8 | C10: seg | D10: =COUNTIF(E10:E16,"<>0") -> 7 | E10: 8 | F10: 7 | G10: 80 | H10: 0 | I10: =(F10*0.64*G10) -> 358.4 | J10: =SUM(I2:I10)/COUNT(I2:I10) -> 274 | K10: =SUm(I3:I10)/7 -> 269.25714 | L10: =SUm(K10:K31)/28 -> 223.17714 | M10: =K10-L10 -> 46.08 | N10: =F10*G10 -> 560 | O10: =sum(N10:N16) -> 4270 | P10: 0 | Q10: 0.8 | R10: 1.3
B11: 9 | C11: ter | E11: 7 | F11: 8 | G11: 100 | H11: 0 | I11: =(F11*0.64*G11) -> 512 | J11: =SUM(I2:I11)/COUNT(I2:I11) -> 300.44444 | K11: =SUm(I4:I11)/7 -> 281.6 | L11: =SUm(K11:K32)/28 -> 213.56082 | M11: =K11-L11 -> 68.039184 | N11: =F11*G11 -> 800 | O11: C.Med | P11: 0 | Q11: 0.8 | R11: 1.3
B12: 10 | C12: qua | E12: 6 | F12: 8 | G12: 80 | H12: 0 | I12: =(F12*0.64*G12) -> 409.6 | J12: =SUM($I$2:I12)/COUNT($I$2:I12) -> 311.36 | K12: =SUm(I5:I12)/7 -> 288.91429 | L12: =SUm(K12:K33)/28 -> 203.50367 | M12: =K12-L12 -> 85.410612 | N12: =F12*G12 -> 640 | O12: =AVERAGE(N10:N16) -> 610 | P12: 0 | Q12: 0.8 | R12: 1.3
B13: 11 | C13: qui | E13: 8 | F13: 7 | G13: 85 | H13: 0 | I13: =(F13*0.64*G13) -> 380.8 | J13: =SUM($I$2:I13)/COUNT($I$2:I13) -> 317.67273 | K13: =SUm(I6:I13)/7 -> 281.14286 | L13: =SUm(K13:K34)/28 -> 193.18531 | M13: =K13-L13 -> 87.957551 | N13: =F13*G13 -> 595 | P13: 0 | Q13: 0.8 | R13: 1.3
B14: 12 | C14: sex | E14: 6 | F14: 5 | G14: 95 | H14: 0 | I14: =(F14*0.64*G14) -> 304 | J14: =SUM($I$2:I14)/COUNT($I$2:I14) -> 316.53333 | K14: =SUm(I7:I14)/7 -> 280.68571 | L14: =SUm(K14:K35)/28 -> 183.14449 | M14: =K14-L14 -> 97.541224 | N14: =F14*G14 -> 475 | P14: 0 | Q14: 0.8 | R14: 1.3
B15: 13 | C15: sab | E15: 7 | F15: 0 | G15: 0 | H15: 0 | I15: =(F15*0.64*G15) -> 0 | J15: =SUM($I$2:I15)/COUNT($I$2:I15) -> 292.18462 | K15: =SUm(I8:I15)/7 -> 280.68571 | L15: =SUm(K15:K36)/28 -> 173.12 | M15: =K15-L15 -> 107.56571 | N15: =F15*G15 -> 0 | P15: 0 | Q15: 0.8 | R15: 1.3
B16: 14 | C16: Dom | E16: 8 | F16: 8 | G16: 150 | H16: 0 | I16: =(F16*0.64*G16) -> 768 | J16: =SUM($I$2:I16)/COUNT($I$2:I16) -> 326.17143 | K16: =SUm(I10:I16)/7 -> 390.4 | L16: =SUm(K16:K37)/28 -> 163.09551 | M16: =K16-L16 -> 227.30449 | N16: =F16*G16 -> 1200 | P16: =O12/(STDEV(N10:N16)) -> 1.6938455 | Q16: 0.8 | R16: 1.3
B17: 15 | C17: seg | D17: =COUNTIF(E17:E23,"<>0") -> 7 | E17: 6 | F17: 7 | G17: 70 | H17: 0 | I17: =(F17*0.64*G17) -> 313.6 | J17: =SUM($I$2:I17)/COUNT($I$2:I17) -> 325.33333 | K17: =SUm(I11:I17)/7 -> 384 | L17: =SUm(K17:K38)/28 -> 149.15265 | M17: =K17-L17 -> 234.84735 | N17: =F17*G17 -> 490 | O17: =sum(N17:N23) -> 2429 | P17: 0 | Q17: 0.8 | R17: 1.3
B18: 16 | C18: ter | E18: 8 | F18: 8 | G18: 75 | H18: 0 | I18: =(F18*0.64*G18) -> 384 | J18: =SUM($I$2:I18)/COUNT($I$2:I18) -> 329 | K18: =SUm(I12:I18)/7 -> 365.71429 | L18: =SUm(K18:K39)/28 -> 135.43837 | M18: =K18-L18 -> 230.27592 | N18: =F18*G18 -> 600 | O18: C.Med | P18: 0 | Q18: 0.8 | R18: 1.3
B19: 17 | C19: qua | E19: 7 | F19: 5 | G19: 40 | H19: 0 | I19: =(F19*0.64*G19) -> 128 | J19: =SUM($I$2:I19)/COUNT($I$2:I19) -> 317.17647 | K19: =SUm(I13:I19)/7 -> 325.48571 | L19: =SUm(K19:K40)/28 -> 122.37714 | M19: =K19-L19 -> 203.10857 | N19: =F19*G19 -> 200 | O19: =AVERAGE(N17:N23) -> 347 | P19: 0 | Q19: 0.8 | R19: 1.3
B20: 18 | C20: qui | E20: 7 | F20: 8 | G20: 80 | H20: 0 | I20: =(F20*0.64*G20) -> 409.6 | J20: =SUM($I$2:I20)/COUNT($I$2:I20) -> 322.31111 | K20: =SUm(I14:I20)/7 -> 329.6 | L20: =SUm(K20:K41)/28 -> 110.75265 | M20: =K20-L20 -> 218.84735 | N20: =F20*G20 -> 640 | P20: 0 | Q20: 0.8 | R20: 1.3
B21: 19 | C21: sex | E21: 7 | F21: 6 | G21: 40 | H21: 0 | I21: =(F21*0.64*G21) -> 153.6 | J21: =SUM($I$2:I21)/COUNT($I$2:I21) -> 313.43158 | K21: =SUm(I15:I21)/7 -> 308.11429 | L21: =SUm(K21:K42)/28 -> 98.981224 | M21: =K21-L21 -> 209.13306 | N21: =F21*G21 -> 240 | P21: 0 | Q21: 0.8 | R21: 1.3
B22: 20 | C22: sab | E22: 5 | F22: 7 | G22: 37 | H22: 0 | I22: =(F22*0.64*G22) -> 165.76 | J22: =SUM($I$2:I22)/COUNT($I$2:I22) -> 306.048 | K22: =SUm(I16:I22)/7 -> 331.79429 | L22: =SUm(K22:K43)/28 -> 87.977143 | M22: =K22-L22 -> 243.81714 | N22: =F22*G22 -> 259 | P22: 0 | Q22: 0.8 | R22: 1.3
B23: 21 | C23: Dom | E23: 7 | F23: 0 | G23: 0 | H23: 0 | I23: =(F23*0.64*G23) -> 0 | J23: =SUM($I$2:I23)/COUNT($I$2:I23) -> 291.47429 | K23: =SUm(I17:I23)/7 -> 222.08 | L23: =SUm(K23:K44)/28 -> 76.127347 | M23: =K23-L23 -> 145.95265 | N23: =F23*G23 -> 0 | P23: =O19/(STDEV(N17:N23)) -> 1.4762216 | Q23: 0.8 | R23: 1.3
B24: 22 | C24: seg | D24: =COUNTIF(E24:E30,"<>0") -> 6 | E24: 8 | F24: 6 | G24: 85 | H24: 0 | I24: =(F24*0.64*G24) -> 326.4 | J24: =SUM($I$2:I24)/COUNT($I$2:I24) -> 293.06182 | K24: =SUm(I18:I24)/7 -> 223.90857 | L24: =SUm(K24:K45)/28 -> 68.195918 | M24: =K24-L24 -> 155.71265 | N24: =F24*G24 -> 510 | O24: =sum(N24:N30) -> 3250 | P24: 0 | Q24: 0.8 | R24: 1.3
B25: 23 | C25: ter | E25: 8 | F25: 8 | G25: 90 | H25: 0 | I25: =(F25*0.64*G25) -> 460.8 | J25: =SUM($I$2:I25)/COUNT($I$2:I25) -> 300.35478 | K25: =SUm(I19:I25)/7 -> 234.88 | L25: =SUm(K25:K46)/28 -> 60.199184 | M25: =K25-L25 -> 174.68082 | N25: =F25*G25 -> 720 | O25: C.Med | P25: 0 | Q25: 0.8 | R25: 1.3
B26: 24 | C26: qua | E26: 7 | F26: 9 | G26: 80 | H26: 0 | I26: =(F26*0.64*G26) -> 460.8 | J26: =SUM($I$2:I26)/COUNT($I$2:I26) -> 307.04 | K26: =SUm(I20:I26)/7 -> 282.42286 | L26: =SUm(K26:K47)/28 -> 51.810612 | M26: =K26-L26 -> 230.61224 | N26: =F26*G26 -> 720 | O26: =AVERAGE(N24:N30) -> 464.28571 | P26: 0 | Q26: 0.8 | R26: 1.3
B27: 25 | C27: qui | E27: 7 | F27: 8 | G27: 75 | H27: 0 | I27: =(F27*0.64*G27) -> 384 | J27: =SUM($I$2:I27)/COUNT($I$2:I27) -> 310.1184 | K27: =SUm(I21:I27)/7 -> 278.76571 | L27: =SUm(K27:K48)/28 -> 41.724082 | M27: =K27-L27 -> 237.04163 | N27: =F27*G27 -> 600 | P27: 0 | Q27: 0.8 | R27: 1.3
B28: 26 | C28: sex | E28: 7 | F28: 6 | G28: 70 | H28: 0 | I28: =(F28*0.64*G28) -> 268.8 | J28: =SUM($I$2:I28)/COUNT($I$2:I28) -> 308.52923 | K28: =SUm(I22:I28)/7 -> 295.22286 | L28: =SUm(K28:K49)/28 -> 31.768163 | M28: =K28-L28 -> 263.45469 | N28: =F28*G28 -> 420 | P28: 0 | Q28: 0.8 | R28: 1.3
B29: 27 | C29: sab | E29: 7 | F29: 7 | G29: 40 | H29: 0 | I29: =(F29*0.64*G29) -> 179.2 | J29: =SUM($I$2:I29)/COUNT($I$2:I29) -> 303.73926 | K29: =SUm(I23:I29)/7 -> 297.14286 | L29: =SUm(K29:K50)/28 -> 21.22449 | M29: =K29-L29 -> 275.91837 | N29: =F29*G29 -> 280 | P29: 0 | Q29: 0.8 | R29: 1.3
B30: 28 | C30: Dom | E30: 0 | F30: 0 | G30: 0 | H30: 0 | I30: =(F30*0.64*G30) -> 0 | J30: =SUM($I$2:I30)/COUNT($I$2:I30) -> 292.89143 | K30: =SUm(I24:I30)/7 -> 297.14286 | L30: =SUm(K30:K51)/28 -> 10.612245 | M30: =K30-L30 -> 286.53061 | N30: =F30*G30 -> 0 | P30: =O26/(STDEV(N24:N30)) -> 1.7919736 | Q30: 0.8 | R30: 1.3
P31: 0
P32: 0
P33: 0
P34: 0
P35: 0
P36: 0
P37: 0
P38: 0
P39: 0
P40: 0
...

Sheet forms
A1: ITEM | B1: DESCRIÇÃO | C1: PONTUAÇÃO (0-5) | D1: valor
A2: 1 | B2: Qualidade do sono | C2: 0 = Muito ruim; 1 = Ruim; 2 = Regular; 3 = Bom; 4 = Muito bom; 5 = Excelente | D2: 2
A3: 2 | B3: Sensação ao acordar | C3: 0 = Muito cansado(a); 1 = Cansado(a); 2 = Pouco cansado(a); 3 = Descansado(a); 4 = Muito descansado(a); 5 = Completamente revitalizado(a) | D3: 2
D4: =SUM(D2:D3) -> 4
B6: dia 1 | C6: =IFERROR(__xludf.DUMMYFUNCTION("IMPORTRANGE(""https://docs.google.com/spreadsheets/d/1tE7dIBIaKMjEtMtxO5wdXZDxAdzqGJB8hKbiZiT-cFI/edit?resourcekey#gid=103428272&range=D2"",""d2"")"),87.0) -> 87
B7: dia 2 | C7: =IFERROR(__xludf.DUMMYFUNCTION("IMPORTRANGE(""https://docs.google.com/spreadsheets/d/1tE7dIBIaKMjEtMtxO5wdXZDxAdzqGJB8hKbiZiT-cFI/edit?resourcekey#gid=103428272&range=D2"",""d3"")"),64.0) -> 64
B8: dia 3 | C8: =IFERROR(__xludf.DUMMYFUNCTION("IMPORTRANGE(""https://docs.google.com/spreadsheets/d/1tE7dIBIaKMjEtMtxO5wdXZDxAdzqGJB8hKbiZiT-cFI/edit?resourcekey#gid=103428272&range=D2"",""d4"")"),82.0) -> 82
B9: dia 4 | C9: =IFERROR(__xludf.DUMMYFUNCTION("IMPORTRANGE(""https://docs.google.com/spreadsheets/d/1tE7dIBIaKMjEtMtxO5wdXZDxAdzqGJB8hKbiZiT-cFI/edit?resourcekey#gid=103428272&range=D2"",""d5"")"),80.0) -> 80
B10: dia 5 | C10: =IFERROR(__xludf.DUMMYFUNCTION("IMPORTRANGE(""https://docs.google.com/spreadsheets/d/1tE7dIBIaKMjEtMtxO5wdXZDxAdzqGJB8hKbiZiT-cFI/edit?resourcekey#gid=103428272&range=D2"",""d6"")"),87.0) -> 87
B11: dia 6 | C11: =IFERROR(__xludf.DUMMYFUNCTION("IMPORTRANGE(""https://docs.google.com/spreadsheets/d/1tE7dIBIaKMjEtMtxO5wdXZDxAdzqGJB8hKbiZiT-cFI/edit?resourcekey#gid=103428272&range=D2"",""d7"")"),"")
B12: dia 7 | C12: =IFERROR(__xludf.DUMMYFUNCTION("IMPORTRANGE(""https://docs.google.com/spreadsheets/d/1tE7dIBIaKMjEtMtxO5wdXZDxAdzqGJB8hKbiZiT-cFI/edit?resourcekey#gid=103428272&range=D2"",""d8"")"),"")
B13: dia 8 | C13: =IFERROR(__xludf.DUMMYFUNCTION("IMPORTRANGE(""https://docs.google.com/spreadsheets/d/1tE7dIBIaKMjEtMtxO5wdXZDxAdzqGJB8hKbiZiT-cFI/edit?resourcekey#gid=103428272&range=D2"",""d9"")"),"")
B14: dia 9 | C14: =IFERROR(__xludf.DUMMYFUNCTION("IMPORTRANGE(""https://docs.google.com/spreadsheets/d/1tE7dIBIaKMjEtMtxO5wdXZDxAdzqGJB8hKbiZiT-cFI/edit?resourcekey#gid=103428272&range=D2"",""d10"")"),"")
B15: dia 10 | C15: =IFERROR(__xludf.DUMMYFUNCTION("IMPORTRANGE(""https://docs.google.com/spreadsheets/d/1tE7dIBIaKMjEtMtxO5wdXZDxAdzqGJB8hKbiZiT-cFI/edit?resourcekey#gid=103428272&range=D2"",""d11"")"),"")
B16: dia 11 | C16: =IFERROR(__xludf.DUMMYFUNCTION("IMPORTRANGE(""https://docs.google.com/spreadsheets/d/1tE7dIBIaKMjEtMtxO5wdXZDxAdzqGJB8hKbiZiT-cFI/edit?resourcekey#gid=103428272&range=D2"",""d12"")"),"")
B17: dia 12 | C17: =IFERROR(__xludf.DUMMYFUNCTION("IMPORTRANGE(""https://docs.google.com/spreadsheets/d/1tE7dIBIaKMjEtMtxO5wdXZDxAdzqGJB8hKbiZiT-cFI/edit?resourcekey#gid=103428272&range=D2"",""d13"")"),"")
B18: dia 13 | C18: =IFERROR(__xludf.DUMMYFUNCTION("IMPORTRANGE(""https://docs.google.com/spreadsheets/d/1tE7dIBIaKMjEtMtxO5wdXZDxAdzqGJB8hKbiZiT-cFI/edit?resourcekey#gid=103428272&range=D2"",""d14"")"),"")
B19: dia 14 | C19: =IFERROR(__xludf.DUMMYFUNCTION("IMPORTRANGE(""https://docs.google.com/spreadsheets/d/1tE7dIBIaKMjEtMtxO5wdXZDxAdzqGJB8hKbiZiT-cFI/edit?resourcekey#gid=103428272&range=D2"",""d15"")"),"")
B20: dia 15 | C20: =IFERROR(__xludf.DUMMYFUNCTION("IMPORTRANGE(""https://docs.google.com/spreadsheets/d/1tE7dIBIaKMjEtMtxO5wdXZDxAdzqGJB8hKbiZiT-cFI/edit?resourcekey#gid=103428272&range=D2"",""d16"")"),"")
B21: dia 16 | C21: =IFERROR(__xludf.DUMMYFUNCTION("IMPORTRANGE(""https://docs.google.com/spreadsheets/d/1tE7dIBIaKMjEtMtxO5wdXZDxAdzqGJB8hKbiZiT-cFI/edit?resourcekey#gid=103428272&range=D2"",""d17"")"),"")
B22: dia 17 | C22: =IFERROR(__xludf.DUMMYFUNCTION("IMPORTRANGE(""https://docs.google.com/spreadsheets/d/1tE7dIBIaKMjEtMtxO5wdXZDxAdzqGJB8hKbiZiT-cFI/edit?resourcekey#gid=103428272&range=D2"",""d18"")"),"")
B23: dia 18 | C23: =IFERROR(__xludf.DUMMYFUNCTION("IMPORTRANGE(""https://docs.google.com/spreadsheets/d/1tE7dIBIaKMjEtMtxO5wdXZDxAdzqGJB8hKbiZiT-cFI/edit?resourcekey#gid=103428272&range=D2"",""d19"")"),"")
B24: dia 19 | C24: =IFERROR(__xludf.DUMMYFUNCTION("IMPORTRANGE(""https://docs.google.com/spreadsheets/d/1tE7dIBIaKMjEtMtxO5wdXZDxAdzqGJB8hKbiZiT-cFI/edit?resourcekey#gid=103428272&range=D2"",""d20"")"),"")
B25: dia 20 | C25: =IFERROR(__xludf.DUMMYFUNCTION("IMPORTRANGE(""https://docs.google.com/spreadsheets/d/1tE7dIBIaKMjEtMtxO5wdXZDxAdzqGJB8hKbiZiT-cFI/edit?resourcekey#gid=103428272&range=D2"",""d21"")"),"")
B26: dia 21 | C26: =IFERROR(__xludf.DUMMYFUNCTION("IMPORTRANGE(""https://docs.google.com/spreadsheets/d/1tE7dIBIaKMjEtMtxO5wdXZDxAdzqGJB8hKbiZiT-cFI/edit?resourcekey#gid=103428272&range=D2"",""d22"")"),"")
B27: dia 22 | C27: =IFERROR(__xludf.DUMMYFUNCTION("IMPORTRANGE(""https://docs.google.com/spreadsheets/d/1tE7dIBIaKMjEtMtxO5wdXZDxAdzqGJB8hKbiZiT-cFI/edit?resourcekey#gid=103428272&range=D2"",""d23"")"),"")
B28: dia 23 | C28: =IFERROR(__xludf.DUMMYFUNCTION("IMPORTRANGE(""https://docs.google.com/spreadsheets/d/1tE7dIBIaKMjEtMtxO5wdXZDxAdzqGJB8hKbiZiT-cFI/edit?resourcekey#gid=103428272&range=D2"",""d24"")"),"")
B29: dia 24 | C29: =IFERROR(__xludf.DUMMYFUNCTION("IMPORTRANGE(""https://docs.google.com/spreadsheets/d/1tE7dIBIaKMjEtMtxO5wdXZDxAdzqGJB8hKbiZiT-cFI/edit?resourcekey#gid=103428272&range=D2"",""d25"")"),"")
B30: dia 25 | C30: =IFERROR(__xludf.DUMMYFUNCTION("IMPORTRANGE(""https://docs.google.com/spreadsheets/d/1tE7dIBIaKMjEtMtxO5wdXZDxAdzqGJB8hKbiZiT-cFI/edit?resourcekey#gid=103428272&range=D2"",""d26"")"),"")
B31: dia 26 | C31: =IFERROR(__xludf.DUMMYFUNCTION("IMPORTRANGE(""https://docs.google.com/spreadsheets/d/1tE7dIBIaKMjEtMtxO5wdXZDxAdzqGJB8hKbiZiT-cFI/edit?resourcekey#gid=103428272&range=D2"",""d27"")"),"")
B32: dia 27 | C32: =IFERROR(__xludf.DUMMYFUNCTION("IMPORTRANGE(""https://docs.google.com/spreadsheets/d/1tE7dIBIaKMjEtMtxO5wdXZDxAdzqGJB8hKbiZiT-cFI/edit?resourcekey#gid=103428272&range=D2"",""d28"")"),"")
B33: dia 28 | C33: =IFERROR(__xludf.DUMMYFUNCTION("IMPORTRANGE(""https://docs.google.com/spreadsheets/d/1tE7dIBIaKMjEtMtxO5wdXZDxAdzqGJB8hKbiZiT-cFI/edit?resourcekey#gid=103428272&range=D2"",""d29"")"),"")

Sheet X
A1: data | B1: treino | C1: Dia semana | D1: dias de treino | E1: avaliação sono | F1: % Rec Sono | G1: % Recup. sono | H1: PSR | I1: PSE | J1: Min | K1: TRIMP | L1: TSS | M1: TSS Cronico | N1: ATL | O1: CTL | P1: TSB | Q1: soma diaria | R1: Soma Semanal | S1: Mono | T1: lim inferior | U1: lim superior | V1: Fator esc. TSS
A2: 45425 | B2: 1 | C2: seg | D2: =COUNTIF(H2:H8,"<>0") -> 3 | F2: 87 | G2: =F2/10 -> 8.7 | H2: 9 | I2: 6 | J2: 58 | K2: =I2*J2 -> 348 | L2: =(I2*J2*$J$2/100) -> 201.84 | M2: =IFERROR(AVERAGE(L2:L8), "N/A") -> 96.445714 | N2: =I2*J2/100 -> 3.48 | O2: 0 | P2: 0 | Q2: =I2*J2 -> 348 | R2: =sum(Q2:Q8) -> 1164 | S2: 0 | T2: 0.8 | U2: 1.3 | V2: 0.8
A3: 45426 | B3: 2 | C3: ter | F3: 64 | G3: =F3/10 -> 6.4 | H3: 6 | I3: 6 | J3: 71 | K3: =I3*J3 -> 426 | L3: =(I3*J3*$J$2/100) -> 247.08 | M3: =IFERROR(AVERAGE(L3:L9), "N/A") -> 67.611429 | N3: =I3*J3/100 -> 4.26 | O3: 0 | P3: 0 | Q3: =I3*J3 -> 426 | R3: C.Med | S3: 0 | T3: 0.8 | U3: 1.3
A4: 45427 | B4: 3 | C4: qua | F4: 82 | G4: =F4/10 -> 8.2 | H4: 8 | I4: 6 | J4: 65 | K4: =I4*J4 -> 390 | L4: =(I4*J4*$J$2/100) -> 226.2 | M4: =IFERROR(AVERAGE(L4:L10), "N/A") -> 32.314286 | N4: =I4*J4/100 -> 3.9 | O4: 0 | P4: 0 | Q4: =I4*J4 -> 390 | R4: =AVERAGE(Q2:Q8) -> 166.28571 | S4: 0 | T4: 0.8 | U4: 1.3
B5: 4 | C5: qui | F5: 0 | G5: =F5/10 -> 0 | H5: 0 | I5: 0 | J5: 0 | K5: =I5*J5 -> 0 | L5: =(I5*J5*$J$2/100) -> 0 | M5: =IFERROR(AVERAGE(L5:L11), "N/A") -> 0 | N5: =I5*J5/100 -> 0 | O5: 0 | P5: 0 | Q5: =I5*J5 -> 0 | S5: 0 | T5: 0.8 | U5: 1.3
B6: 5 | C6: sex | F6: 0 | G6: =F6/10 -> 0 | H6: 0 | I6: 0 | J6: 0 | K6: =I6*J6 -> 0 | L6: =(I6*J6*$J$2/100) -> 0 | M6: =IFERROR(AVERAGE(L6:L12), "N/A") -> 0 | N6: =I6*J6/100 -> 0 | O6: 0 | P6: 0 | Q6: =I6*J6 -> 0 | S6: 0 | T6: 0.8 | U6: 1.3
B7: 6 | C7: sab | F7: 0 | G7: =F7/10 -> 0 | H7: 0 | I7: 0 | J7: 0 | K7: =I7*J7 -> 0 | L7: =(I7*J7*$J$2/100) -> 0 | M7: =IFERROR(AVERAGE(L7:L13), "N/A") -> 0 | N7: =I7*J7/100 -> 0 | O7: 0 | P7: 0 | Q7: =I7*J7 -> 0 | S7: 0 | T7: 0.8 | U7: 1.3
B8: 7 | C8: dom | F8: 0 | G8: =F8/10 -> 0 | H8: 0 | I8: 0 | J8: 0 | K8: =I8*J8 -> 0 | L8: =(I8*J8*$J$2/100) -> 0 | M8: =IFERROR(AVERAGE(L8:L14), "N/A") -> 0 | N8: =I8*J8/100 -> 0 | O8: =AVERAGE(N2:N8) -> 1.6628571 | P8: =O8-N8 -> 1.6628571 | Q8: =I8*J8 -> 0 | S8: =R4/(STDEV(Q2:Q8)) -> 0.79709052 | T8: 0.8 | U8: 1.3 | W8: Pearson PSE PSR | AB8: =correl(H2:H8,I2:I8) -> 0.97761763 | AD8: Pearson PSE Sono | AI8: =correl(G2:G8,I2:I8) -> 0.98614235 | AK8: Pearson PSR Sono | AP8: =correl(F2:F8,H2:H8) -> 0.99870039
B9: 8 | C9: seg | D9: =COUNTIF(H9:H15,"<>0") -> 0 | F9: 0 | G9: =F9/10 -> 0 | H9: 0 | I9: 0 | J9: 0 | K9: =I9*J9 -> 0 | L9: =(I9*J9*$J$2/100) -> 0 | M9: =AVERAGE(L2:L8) -> 96.445714 | N9: =I9*J9/100 -> 0 | O9: =AVERAGE(N3:N9) -> 1.1657143 | P9: =O9-N9 -> 1.1657143 | Q9: =I9*J9 -> 0 | R9: =sum(Q9:Q15) -> 0 | S9: 0 | T9: 0.8 | U9: 1.3
B10: 9 | C10: ter | F10: 0 | G10: =F10/10 -> 0 | H10: 0 | I10: 0 | J10: 0 | K10: =I10*J10 -> 0 | L10: =(I10*J10*$J$2/100) -> 0 | M10: =AVERAGE(L3:L9) -> 67.611429 | N10: =I10*J10/100 -> 0 | O10: =AVERAGE(N4:N10) -> 0.55714286 | P10: =O10-N10 -> 0.55714286 | Q10: =I10*J10 -> 0 | R10: C.Med | S10: 0 | T10: 0.8 | U10: 1.3
B11: 10 | C11: qua | F11: 0 | G11: =F11/10 -> 0 | H11: 0 | I11: 0 | J11: 0 | K11: =I11*J11 -> 0 | L11: =(I11*J11*$J$2/100) -> 0 | M11: =AVERAGE(L4:L10) -> 32.314286 | N11: =I11*J11/100 -> 0 | O11: =AVERAGE(N5:N11) -> 0 | P11: =O11-N11 -> 0 | Q11: =I11*J11 -> 0 | R11: =AVERAGE(Q9:Q15) -> 0 | S11: 0 | T11: 0.8 | U11: 1.3
B12: 11 | C12: qui | F12: 0 | G12: =F12/10 -> 0 | H12: 0 | I12: 0 | J12: 0 | K12: =I12*J12 -> 0 | L12: =(I12*J12*$J$2/100) -> 0 | M12: =AVERAGE(L5:L11) -> 0 | N12: =I12*J12/100 -> 0 | O12: =AVERAGE(N6:N12) -> 0 | P12: =O12-N12 -> 0 | Q12: =I12*J12 -> 0 | S12: 0 | T12: 0.8 | U12: 1.3
B13: 12 | C13: sex | F13: 0 | G13: =F13/10 -> 0 | H13: 0 | I13: 0 | J13: 0 | K13: =I13*J13 -> 0 | L13: =(I13*J13*$J$2/100) -> 0 | M13: =AVERAGE(L6:L12) -> 0 | N13: =I13*J13/100 -> 0 | O13: =AVERAGE(N7:N13) -> 0 | P13: =O13-N13 -> 0 | Q13: =I13*J13 -> 0 | S13: 0 | T13: 0.8 | U13: 1.3
